Workbook

Sheet Total
B2: Count | E2: Drops
A3: Arcana | B3: First | C3: Second | D3: % | E3: 1 | F3: 2 | G3: 3 | H3: 4 | I3: 5 | J3: 6 | K3: 7 | L3: 8 | M3: 9 | N3: 10 | O3: 11 | P3: 12 | Q3: 13 | R3: 14 | S3: 15 | T3: 16 | U3: 17 | V3: 18 | W3: 19 | X3: 20 | Y3: 21 | Z3: 22 | AA3: 23 | AB3: 24 | AC3: 25 | AD3: 26 | AE3: 27 | AF3: 28 | AG3: 29 | AH3: 30 | AI3: 31 | AJ3: 32 | AK3: 33 | AL3: 34 | AM3: 35 | AN3: 36 | AO3: 37 | AP3: 38 | AQ3: 39 | AR3: 40
A4: 1 | B4: =Navia!I4+Clorinde!I4+Neuvilette!I4+Shogun!I4+Mualani!I4+Ineffa!I4 -> 3 | C4: =Navia!J4+Clorinde!J4+Neuvilette!J4+Shogun!J4+Mualani!J4+Ineffa!J4 -> 2 | D4: 3.04 | E4: =MAX(MIN($D4-E$3*0.5,1),0) -> 1 | F4: =MAX(MIN($D4-F$3*0.5,1),0) -> 1 | G4: =MAX(MIN($D4-G$3*0.5,1),0) -> 1 | H4: =MAX(MIN($D4-H$3*0.5,1),0) -> 1 | I4: =MAX(MIN($D4-I$3*0.5,1),0) -> 0.54 | J4: =MAX(MIN($D4-J$3*0.5,1),0) -> 0.04 | K4: =MAX(MIN($D4-K$3*0.5,1),0) -> 0 | L4: =MAX(MIN($D4-L$3*0.5,1),0) -> 0 | ... AR4: =MAX(MIN($D4-AR$3*0.5,1),0) -> 0
A5: 2 | B5: =Navia!I5+Clorinde!I5+Neuvilette!I5+Shogun!I5+Mualani!I5+Ineffa!I5 -> 4 | C5: =Navia!J5+Clorinde!J5+Neuvilette!J5+Shogun!J5+Mualani!J5+Ineffa!J5 -> 6 | D5: 6.12 | E5: =MAX(MIN($D5-E$3*0.5,1),0) -> 1 | F5: =MAX(MIN($D5-F$3*0.5,1),0) -> 1 | G5: =MAX(MIN($D5-G$3*0.5,1),0) -> 1 | H5: =MAX(MIN($D5-H$3*0.5,1),0) -> 1 | I5: =MAX(MIN($D5-I$3*0.5,1),0) -> 1 | J5: =MAX(MIN($D5-J$3*0.5,1),0) -> 1 | K5: =MAX(MIN($D5-K$3*0.5,1),0) -> 1 | L5: =MAX(MIN($D5-L$3*0.5,1),0) -> 1 | ... AR5: =MAX(MIN($D5-AR$3*0.5,1),0) -> 0
A6: 3 | B6: =Navia!I6+Clorinde!I6+Neuvilette!I6+Shogun!I6+Mualani!I6+Ineffa!I6 -> 4 | C6: =Navia!J6+Clorinde!J6+Neuvilette!J6+Shogun!J6+Mualani!J6+Ineffa!J6 -> 7 | D6: 6.73 | E6: =MAX(MIN($D6-E$3*0.5,1),0) -> 1 | F6: =MAX(MIN($D6-F$3*0.5,1),0) -> 1 | G6: =MAX(MIN($D6-G$3*0.5,1),0) -> 1 | H6: =MAX(MIN($D6-H$3*0.5,1),0) -> 1 | I6: =MAX(MIN($D6-I$3*0.5,1),0) -> 1 | J6: =MAX(MIN($D6-J$3*0.5,1),0) -> 1 | K6: =MAX(MIN($D6-K$3*0.5,1),0) -> 1 | L6: =MAX(MIN($D6-L$3*0.5,1),0) -> 1 | ... AR6: =MAX(MIN($D6-AR$3*0.5,1),0) -> 0
A7: 4 | B7: =Navia!I7+Clorinde!I7+Neuvilette!I7+Shogun!I7+Mualani!I7+Ineffa!I7 -> 3 | C7: =Navia!J7+Clorinde!J7+Neuvilette!J7+Shogun!J7+Mualani!J7+Ineffa!J7 -> 3 | D7: 3.65 | E7: =MAX(MIN($D7-E$3*0.5,1),0) -> 1 | F7: =MAX(MIN($D7-F$3*0.5,1),0) -> 1 | G7: =MAX(MIN($D7-G$3*0.5,1),0) -> 1 | H7: =MAX(MIN($D7-H$3*0.5,1),0) -> 1 | I7: =MAX(MIN($D7-I$3*0.5,1),0) -> 1 | J7: =MAX(MIN($D7-J$3*0.5,1),0) -> 0.65 | K7: =MAX(MIN($D7-K$3*0.5,1),0) -> 0.15 | L7: =MAX(MIN($D7-L$3*0.5,1),0) -> 0 | ... AR7: =MAX(MIN($D7-AR$3*0.5,1),0) -> 0
A8: 5 | B8: =Navia!I8+Clorinde!I8+Neuvilette!I8+Shogun!I8+Mualani!I8+Ineffa!I8 -> 2 | C8: =Navia!J8+Clorinde!J8+Neuvilette!J8+Shogun!J8+Mualani!J8+Ineffa!J8 -> 3 | D8: 3.02 | E8: =MAX(MIN($D8-E$3*0.5,1),0) -> 1 | F8: =MAX(MIN($D8-F$3*0.5,1),0) -> 1 | G8: =MAX(MIN($D8-G$3*0.5,1),0) -> 1 | H8: =MAX(MIN($D8-H$3*0.5,1),0) -> 1 | I8: =MAX(MIN($D8-I$3*0.5,1),0) -> 0.52 | J8: =MAX(MIN($D8-J$3*0.5,1),0) -> 0.02 | K8: =MAX(MIN($D8-K$3*0.5,1),0) -> 0 | L8: =MAX(MIN($D8-L$3*0.5,1),0) -> 0 | ... AR8: =MAX(MIN($D8-AR$3*0.5,1),0) -> 0
A9: 6 | B9: =Navia!I9+Clorinde!I9+Neuvilette!I9+Shogun!I9+Mualani!I9+Ineffa!I9 -> 12 | C9: =Navia!J9+Clorinde!J9+Neuvilette!J9+Shogun!J9+Mualani!J9+Ineffa!J9 -> 2 | D9: 10.3 | E9: =MAX(MIN($D9-E$3*0.5,1),0) -> 1 | F9: =MAX(MIN($D9-F$3*0.5,1),0) -> 1 | G9: =MAX(MIN($D9-G$3*0.5,1),0) -> 1 | H9: =MAX(MIN($D9-H$3*0.5,1),0) -> 1 | I9: =MAX(MIN($D9-I$3*0.5,1),0) -> 1 | J9: =MAX(MIN($D9-J$3*0.5,1),0) -> 1 | K9: =MAX(MIN($D9-K$3*0.5,1),0) -> 1 | L9: =MAX(MIN($D9-L$3*0.5,1),0) -> 1 | ... AR9: =MAX(MIN($D9-AR$3*0.5,1),0) -> 0
A10: 7 | B10: =Navia!I10+Clorinde!I10+Neuvilette!I10+Shogun!I10+Mualani!I10+Ineffa!I10 -> 9 | C10: =Navia!J10+Clorinde!J10+Neuvilette!J10+Shogun!J10+Mualani!J10+Ineffa!J10 -> 8 | D10: 9.58 | E10: =MAX(MIN($D10-E$3*0.5,1),0) -> 1 | F10: =MAX(MIN($D10-F$3*0.5,1),0) -> 1 | G10: =MAX(MIN($D10-G$3*0.5,1),0) -> 1 | H10: =MAX(MIN($D10-H$3*0.5,1),0) -> 1 | I10: =MAX(MIN($D10-I$3*0.5,1),0) -> 1 | J10: =MAX(MIN($D10-J$3*0.5,1),0) -> 1 | K10: =MAX(MIN($D10-K$3*0.5,1),0) -> 1 | L10: =MAX(MIN($D10-L$3*0.5,1),0) -> 1 | ... AR10: =MAX(MIN($D10-AR$3*0.5,1),0) -> 0
A11: 8 | B11: =Navia!I11+Clorinde!I11+Neuvilette!I11+Shogun!I11+Mualani!I11+Ineffa!I11 -> 2 | C11: =Navia!J11+Clorinde!J11+Neuvilette!J11+Shogun!J11+Mualani!J11+Ineffa!J11 -> 10 | D11: 7.25 | E11: =MAX(MIN($D11-E$3*0.5,1),0) -> 1 | F11: =MAX(MIN($D11-F$3*0.5,1),0) -> 1 | G11: =MAX(MIN($D11-G$3*0.5,1),0) -> 1 | H11: =MAX(MIN($D11-H$3*0.5,1),0) -> 1 | I11: =MAX(MIN($D11-I$3*0.5,1),0) -> 1 | J11: =MAX(MIN($D11-J$3*0.5,1),0) -> 1 | K11: =MAX(MIN($D11-K$3*0.5,1),0) -> 1 | L11: =MAX(MIN($D11-L$3*0.5,1),0) -> 1 | ... AR11: =MAX(MIN($D11-AR$3*0.5,1),0) -> 0
A12: 9 | B12: =Navia!I12+Clorinde!I12+Neuvilette!I12+Shogun!I12+Mualani!I12+Ineffa!I12 -> 1 | C12: =Navia!J12+Clorinde!J12+Neuvilette!J12+Shogun!J12+Mualani!J12+Ineffa!J12 -> 3 | D12: 2.4 | E12: =MAX(MIN($D12-E$3*0.5,1),0) -> 1 | F12: =MAX(MIN($D12-F$3*0.5,1),0) -> 1 | G12: =MAX(MIN($D12-G$3*0.5,1),0) -> 0.9 | H12: =MAX(MIN($D12-H$3*0.5,1),0) -> 0.4 | I12: =MAX(MIN($D12-I$3*0.5,1),0) -> 0 | J12: =MAX(MIN($D12-J$3*0.5,1),0) -> 0 | K12: =MAX(MIN($D12-K$3*0.5,1),0) -> 0 | L12: =MAX(MIN($D12-L$3*0.5,1),0) -> 0 | ... AR12: =MAX(MIN($D12-AR$3*0.5,1),0) -> 0
A13: 10 | B13: =Navia!I13+Clorinde!I13+Neuvilette!I13+Shogun!I13+Mualani!I13+Ineffa!I13 -> 3 | C13: =Navia!J13+Clorinde!J13+Neuvilette!J13+Shogun!J13+Mualani!J13+Ineffa!J13 -> 1 | D13: 2.43 | E13: =MAX(MIN($D13-E$3*0.5,1),0) -> 1 | F13: =MAX(MIN($D13-F$3*0.5,1),0) -> 1 | G13: =MAX(MIN($D13-G$3*0.5,1),0) -> 0.93 | H13: =MAX(MIN($D13-H$3*0.5,1),0) -> 0.43 | I13: =MAX(MIN($D13-I$3*0.5,1),0) -> 0 | J13: =MAX(MIN($D13-J$3*0.5,1),0) -> 0 | K13: =MAX(MIN($D13-K$3*0.5,1),0) -> 0 | L13: =MAX(MIN($D13-L$3*0.5,1),0) -> 0 | ... AR13: =MAX(MIN($D13-AR$3*0.5,1),0) -> 0
A14: 11 | B14: =Navia!I14+Clorinde!I14+Neuvilette!I14+Shogun!I14+Mualani!I14+Ineffa!I14 -> 5 | C14: =Navia!J14+Clorinde!J14+Neuvilette!J14+Shogun!J14+Mualani!J14+Ineffa!J14 -> 6 | D14: 6.78 | E14: =MAX(MIN($D14-E$3*0.5,1),0) -> 1 | F14: =MAX(MIN($D14-F$3*0.5,1),0) -> 1 | G14: =MAX(MIN($D14-G$3*0.5,1),0) -> 1 | H14: =MAX(MIN($D14-H$3*0.5,1),0) -> 1 | I14: =MAX(MIN($D14-I$3*0.5,1),0) -> 1 | J14: =MAX(MIN($D14-J$3*0.5,1),0) -> 1 | K14: =MAX(MIN($D14-K$3*0.5,1),0) -> 1 | L14: =MAX(MIN($D14-L$3*0.5,1),0) -> 1 | ... AR14: =MAX(MIN($D14-AR$3*0.5,1),0) -> 0
A15: 12 | B15: =Navia!I15+Clorinde!I15+Neuvilette!I15+Shogun!I15+Mualani!I15+Ineffa!I15 -> 1 | C15: =Navia!J15+Clorinde!J15+Neuvilette!J15+Shogun!J15+Mualani!J15+Ineffa!J15 -> 0 | D15: 0.6 | E15: =MAX(MIN($D15-E$3*0.5,1),0) -> 0.1 | F15: =MAX(MIN($D15-F$3*0.5,1),0) -> 0 | G15: =MAX(MIN($D15-G$3*0.5,1),0) -> 0 | H15: =MAX(MIN($D15-H$3*0.5,1),0) -> 0 | I15: =MAX(MIN($D15-I$3*0.5,1),0) -> 0 | J15: =MAX(MIN($D15-J$3*0.5,1),0) -> 0 | K15: =MAX(MIN($D15-K$3*0.5,1),0) -> 0 | L15: =MAX(MIN($D15-L$3*0.5,1),0) -> 0 | ... AR15: =MAX(MIN($D15-AR$3*0.5,1),0) -> 0
... A25: 22 | B25: =Navia!I25+Clorinde!I25+Neuvilette!I25+Shogun!I25+Mualani!I25+Ineffa!I25 -> 0 | C25: =Navia!J25+Clorinde!J25+Neuvilette!J25+Shogun!J25+Mualani!J25+Ineffa!J25 -> 2 | D25: 1.19 | E25: =MAX(MIN($D25-E$3*0.5,1),0) -> 0.69 | F25: =MAX(MIN($D25-F$3*0.5,1),0) -> 0.19 | G25: =MAX(MIN($D25-G$3*0.5,1),0) -> 0 | H25: =MAX(MIN($D25-H$3*0.5,1),0) -> 0 | I25: =MAX(MIN($D25-I$3*0.5,1),0) -> 0 | J25: =MAX(MIN($D25-J$3*0.5,1),0) -> 0 | K25: =MAX(MIN($D25-K$3*0.5,1),0) -> 0 | L25: =MAX(MIN($D25-L$3*0.5,1),0) -> 0 | ... AR25: =MAX(MIN($D25-AR$3*0.5,1),0) -> 0
A26: Total | B26: =SUM(B4:B25)+SUM(C4:C25) -> 162

Sheet Navia
I2: Count | L2: Drops
B3: Run | C3: First | E3: Second | H3: Arcana | I3: First | J3: Second | K3: % | L3: 1 | M3: 2 | N3: 3 | O3: 4 | P3: 5 | Q3: 6 | R3: 7 | S3: 8 | T3: 9 | U3: 10 | V3: 11 | W3: 12 | X3: 13 | Y3: 14 | Z3: 15 | AA3: 16 | AB3: 17 | AC3: 18 | AD3: 19 | AE3: 20 | AF3: 21 | AG3: 22 | AH3: 23 | AI3: 24 | AJ3: 25 | AK3: 26 | AL3: 27 | AM3: 28 | AN3: 29 | AO3: 30 | AP3: 31 | AQ3: 32 | AR3: 33 | AS3: 34 | AT3: 35 | AU3: 36 | AV3: 37 | AW3: 38 | AX3: 39 | AY3: 40
B4: 1 | C4: 21 | D4: World | E4: 6 | F4: Lovers | H4: 1 | I4: =COUNTIF($C$4:$C$16,H4) -> 0 | J4: =COUNTIF($E$4:$E$16,H4) -> 0 | K4: 0 | L4: =MAX(MIN($K4-L$3*0.5,1),0) -> 0 | M4: =MAX(MIN($K4-M$3*0.5,1),0) -> 0 | N4: =MAX(MIN($K4-N$3*0.5,1),0) -> 0 | O4: =MAX(MIN($K4-O$3*0.5,1),0) -> 0 | P4: =MAX(MIN($K4-P$3*0.5,1),0) -> 0 | Q4: =MAX(MIN($K4-Q$3*0.5,1),0) -> 0 | R4: =MAX(MIN($K4-R$3*0.5,1),0) -> 0 | S4: =MAX(MIN($K4-S$3*0.5,1),0) -> 0 | ... AY4: =MAX(MIN($K4-AY$3*0.5,1),0) -> 0
B5: 2 | C5: 15 | D5: Devil | E5: 8 | F5: Strength | H5: 2 | I5: =COUNTIF($C$4:$C$16,H5) -> 1 | J5: =COUNTIF($E$4:$E$16,H5) -> 0 | K5: 3.78 | L5: =MAX(MIN($K5-L$3*0.5,1),0) -> 1 | M5: =MAX(MIN($K5-M$3*0.5,1),0) -> 1 | N5: =MAX(MIN($K5-N$3*0.5,1),0) -> 1 | O5: =MAX(MIN($K5-O$3*0.5,1),0) -> 1 | P5: =MAX(MIN($K5-P$3*0.5,1),0) -> 1 | Q5: =MAX(MIN($K5-Q$3*0.5,1),0) -> 0.78 | R5: =MAX(MIN($K5-R$3*0.5,1),0) -> 0.28 | S5: =MAX(MIN($K5-S$3*0.5,1),0) -> 0 | ... AY5: =MAX(MIN($K5-AY$3*0.5,1),0) -> 0
B6: 3 | C6: 7 | D6: Chariot | E6: 4 | F6: Emperor | H6: 3 | I6: =COUNTIF($C$4:$C$16,H6) -> 1 | J6: =COUNTIF($E$4:$E$16,H6) -> 2 | K6: 11.39 | L6: =MAX(MIN($K6-L$3*0.5,1),0) -> 1 | M6: =MAX(MIN($K6-M$3*0.5,1),0) -> 1 | N6: =MAX(MIN($K6-N$3*0.5,1),0) -> 1 | O6: =MAX(MIN($K6-O$3*0.5,1),0) -> 1 | P6: =MAX(MIN($K6-P$3*0.5,1),0) -> 1 | Q6: =MAX(MIN($K6-Q$3*0.5,1),0) -> 1 | R6: =MAX(MIN($K6-R$3*0.5,1),0) -> 1 | S6: =MAX(MIN($K6-S$3*0.5,1),0) -> 1 | ... AY6: =MAX(MIN($K6-AY$3*0.5,1),0) -> 0
B7: 4 | C7: 2 | D7: Priestess | E7: 20 | F7: Judgment | H7: 4 | I7: =COUNTIF($C$4:$C$16,H7) -> 0 | J7: =COUNTIF($E$4:$E$16,H7) -> 1 | K7: 3.64 | L7: =MAX(MIN($K7-L$3*0.5,1),0) -> 1 | M7: =MAX(MIN($K7-M$3*0.5,1),0) -> 1 | N7: =MAX(MIN($K7-N$3*0.5,1),0) -> 1 | O7: =MAX(MIN($K7-O$3*0.5,1),0) -> 1 | P7: =MAX(MIN($K7-P$3*0.5,1),0) -> 1 | Q7: =MAX(MIN($K7-Q$3*0.5,1),0) -> 0.64 | R7: =MAX(MIN($K7-R$3*0.5,1),0) -> 0.14 | S7: =MAX(MIN($K7-S$3*0.5,1),0) -> 0 | ... AY7: =MAX(MIN($K7-AY$3*0.5,1),0) -> 0
B8: 5 | C8: 19 | D8: Sun | E8: 3 | F8: Empress | H8: 5 | I8: =COUNTIF($C$4:$C$16,H8) -> 0 | J8: =COUNTIF($E$4:$E$16,H8) -> 2 | K8: 7.27 | L8: =MAX(MIN($K8-L$3*0.5,1),0) -> 1 | M8: =MAX(MIN($K8-M$3*0.5,1),0) -> 1 | N8: =MAX(MIN($K8-N$3*0.5,1),0) -> 1 | O8: =MAX(MIN($K8-O$3*0.5,1),0) -> 1 | P8: =MAX(MIN($K8-P$3*0.5,1),0) -> 1 | Q8: =MAX(MIN($K8-Q$3*0.5,1),0) -> 1 | R8: =MAX(MIN($K8-R$3*0.5,1),0) -> 1 | S8: =MAX(MIN($K8-S$3*0.5,1),0) -> 1 | ... AY8: =MAX(MIN($K8-AY$3*0.5,1),0) -> 0
B9: 6 | C9: 10 | D9: Wheel | E9: 3 | F9: Empress | H9: 6 | I9: =COUNTIF($C$4:$C$16,H9) -> 2 | J9: =COUNTIF($E$4:$E$16,H9) -> 1 | K9: 11.89 | L9: =MAX(MIN($K9-L$3*0.5,1),0) -> 1 | M9: =MAX(MIN($K9-M$3*0.5,1),0) -> 1 | N9: =MAX(MIN($K9-N$3*0.5,1),0) -> 1 | O9: =MAX(MIN($K9-O$3*0.5,1),0) -> 1 | P9: =MAX(MIN($K9-P$3*0.5,1),0) -> 1 | Q9: =MAX(MIN($K9-Q$3*0.5,1),0) -> 1 | R9: =MAX(MIN($K9-R$3*0.5,1),0) -> 1 | S9: =MAX(MIN($K9-S$3*0.5,1),0) -> 1 | ... AY9: =MAX(MIN($K9-AY$3*0.5,1),0) -> 0
B10: 7 | C10: 3 | D10: Empress | E10: 5 | F10: Hierophant | H10: 7 | I10: =COUNTIF($C$4:$C$16,H10) -> 2 | J10: =COUNTIF($E$4:$E$16,H10) -> 2 | K10: 15.93 | L10: =MAX(MIN($K10-L$3*0.5,1),0) -> 1 | M10: =MAX(MIN($K10-M$3*0.5,1),0) -> 1 | N10: =MAX(MIN($K10-N$3*0.5,1),0) -> 1 | O10: =MAX(MIN($K10-O$3*0.5,1),0) -> 1 | P10: =MAX(MIN($K10-P$3*0.5,1),0) -> 1 | Q10: =MAX(MIN($K10-Q$3*0.5,1),0) -> 1 | R10: =MAX(MIN($K10-R$3*0.5,1),0) -> 1 | S10: =MAX(MIN($K10-S$3*0.5,1),0) -> 1 | ... AY10: =MAX(MIN($K10-AY$3*0.5,1),0) -> 0
B11: 8 | C11: 6 | D11: Lovers | E11: 7 | F11: Chariot | H11: 8 | I11: =COUNTIF($C$4:$C$16,H11) -> 0 | J11: =COUNTIF($E$4:$E$16,H11) -> 3 | K11: 10.91 | L11: =MAX(MIN($K11-L$3*0.5,1),0) -> 1 | M11: =MAX(MIN($K11-M$3*0.5,1),0) -> 1 | N11: =MAX(MIN($K11-N$3*0.5,1),0) -> 1 | O11: =MAX(MIN($K11-O$3*0.5,1),0) -> 1 | P11: =MAX(MIN($K11-P$3*0.5,1),0) -> 1 | Q11: =MAX(MIN($K11-Q$3*0.5,1),0) -> 1 | R11: =MAX(MIN($K11-R$3*0.5,1),0) -> 1 | S11: =MAX(MIN($K11-S$3*0.5,1),0) -> 1 | ... AY11: =MAX(MIN($K11-AY$3*0.5,1),0) -> 0
B12: 9 | C12: 19 | D12: Sun | E12: 7 | F12: Chariot | H12: 9 | I12: =COUNTIF($C$4:$C$16,H12) -> 0 | J12: =COUNTIF($E$4:$E$16,H12) -> 0 | K12: 0 | L12: =MAX(MIN($K12-L$3*0.5,1),0) -> 0 | M12: =MAX(MIN($K12-M$3*0.5,1),0) -> 0 | N12: =MAX(MIN($K12-N$3*0.5,1),0) -> 0 | O12: =MAX(MIN($K12-O$3*0.5,1),0) -> 0 | P12: =MAX(MIN($K12-P$3*0.5,1),0) -> 0 | Q12: =MAX(MIN($K12-Q$3*0.5,1),0) -> 0 | R12: =MAX(MIN($K12-R$3*0.5,1),0) -> 0 | S12: =MAX(MIN($K12-S$3*0.5,1),0) -> 0 | ... AY12: =MAX(MIN($K12-AY$3*0.5,1),0) -> 0
B13: 10 | C13: 21 | D13: World | E13: 8 | F13: Strength | H13: 10 | I13: =COUNTIF($C$4:$C$16,H13) -> 1 | J13: =COUNTIF($E$4:$E$16,H13) -> 0 | K13: 3.78 | L13: =MAX(MIN($K13-L$3*0.5,1),0) -> 1 | M13: =MAX(MIN($K13-M$3*0.5,1),0) -> 1 | N13: =MAX(MIN($K13-N$3*0.5,1),0) -> 1 | O13: =MAX(MIN($K13-O$3*0.5,1),0) -> 1 | P13: =MAX(MIN($K13-P$3*0.5,1),0) -> 1 | Q13: =MAX(MIN($K13-Q$3*0.5,1),0) -> 0.78 | R13: =MAX(MIN($K13-R$3*0.5,1),0) -> 0.28 | S13: =MAX(MIN($K13-S$3*0.5,1),0) -> 0 | ... AY13: =MAX(MIN($K13-AY$3*0.5,1),0) -> 0
B14: 11 | C14: 7 | D14: Chariot | E14: 5 | F14: Hierophant | H14: 11 | I14: =COUNTIF($C$4:$C$16,H14) -> 0 | J14: =COUNTIF($E$4:$E$16,H14) -> 0 | K14: 0 | L14: =MAX(MIN($K14-L$3*0.5,1),0) -> 0 | M14: =MAX(MIN($K14-M$3*0.5,1),0) -> 0 | N14: =MAX(MIN($K14-N$3*0.5,1),0) -> 0 | O14: =MAX(MIN($K14-O$3*0.5,1),0) -> 0 | P14: =MAX(MIN($K14-P$3*0.5,1),0) -> 0 | Q14: =MAX(MIN($K14-Q$3*0.5,1),0) -> 0 | R14: =MAX(MIN($K14-R$3*0.5,1),0) -> 0 | S14: =MAX(MIN($K14-S$3*0.5,1),0) -> 0 | ... AY14: =MAX(MIN($K14-AY$3*0.5,1),0) -> 0
B15: 12 | C15: 19 | D15: Sun | E15: 14 | F15: Temperance | H15: 12 | I15: =COUNTIF($C$4:$C$16,H15) -> 0 | J15: =COUNTIF($E$4:$E$16,H15) -> 0 | K15: 0 | L15: =MAX(MIN($K15-L$3*0.5,1),0) -> 0 | M15: =MAX(MIN($K15-M$3*0.5,1),0) -> 0 | N15: =MAX(MIN($K15-N$3*0.5,1),0) -> 0 | O15: =MAX(MIN($K15-O$3*0.5,1),0) -> 0 | P15: =MAX(MIN($K15-P$3*0.5,1),0) -> 0 | Q15: =MAX(MIN($K15-Q$3*0.5,1),0) -> 0 | R15: =MAX(MIN($K15-R$3*0.5,1),0) -> 0 | S15: =MAX(MIN($K15-S$3*0.5,1),0) -> 0 | ... AY15: =MAX(MIN($K15-AY$3*0.5,1),0) -> 0
B16: 13 | C16: 6 | D16: Lovers | E16: 8 | F16: Strength | H16: 13 | I16: =COUNTIF($C$4:$C$16,H16) -> 0 | J16: =COUNTIF($E$4:$E$16,H16) -> 0 | K16: 0 | L16: =MAX(MIN($K16-L$3*0.5,1),0) -> 0 | M16: =MAX(MIN($K16-M$3*0.5,1),0) -> 0 | N16: =MAX(MIN($K16-N$3*0.5,1),0) -> 0 | O16: =MAX(MIN($K16-O$3*0.5,1),0) -> 0 | P16: =MAX(MIN($K16-P$3*0.5,1),0) -> 0 | Q16: =MAX(MIN($K16-Q$3*0.5,1),0) -> 0 | R16: =MAX(MIN($K16-R$3*0.5,1),0) -> 0 | S16: =MAX(MIN($K16-S$3*0.5,1),0) -> 0 | ... AY16: =MAX(MIN($K16-AY$3*0.5,1),0) -> 0
H17: 14 | I17: =COUNTIF($C$4:$C$16,H17) -> 0 | J17: =COUNTIF($E$4:$E$16,H17) -> 1 | K17: 3.64 | L17: =MAX(MIN($K17-L$3*0.5,1),0) -> 1 | M17: =MAX(MIN($K17-M$3*0.5,1),0) -> 1 | N17: =MAX(MIN($K17-N$3*0.5,1),0) -> 1 | O17: =MAX(MIN($K17-O$3*0.5,1),0) -> 1 | P17: =MAX(MIN($K17-P$3*0.5,1),0) -> 1 | Q17: =MAX(MIN($K17-Q$3*0.5,1),0) -> 0.64 | R17: =MAX(MIN($K17-R$3*0.5,1),0) -> 0.14 | S17: =MAX(MIN($K17-S$3*0.5,1),0) -> 0 | ... AY17: =MAX(MIN($K17-AY$3*0.5,1),0) -> 0
H18: 15 | I18: =COUNTIF($C$4:$C$16,H18) -> 1 | J18: =COUNTIF($E$4:$E$16,H18) -> 0 | K18: 3.78 | L18: =MAX(MIN($K18-L$3*0.5,1),0) -> 1 | M18: =MAX(MIN($K18-M$3*0.5,1),0) -> 1 | N18: =MAX(MIN($K18-N$3*0.5,1),0) -> 1 | O18: =MAX(MIN($K18-O$3*0.5,1),0) -> 1 | P18: =MAX(MIN($K18-P$3*0.5,1),0) -> 1 | Q18: =MAX(MIN($K18-Q$3*0.5,1),0) -> 0.78 | R18: =MAX(MIN($K18-R$3*0.5,1),0) -> 0.28 | S18: =MAX(MIN($K18-S$3*0.5,1),0) -> 0 | ... AY18: =MAX(MIN($K18-AY$3*0.5,1),0) -> 0
H19: 16 | I19: =COUNTIF($C$4:$C$16,H19) -> 0 | J19: =COUNTIF($E$4:$E$16,H19) -> 0 | K19: 0 | L19: =MAX(MIN($K19-L$3*0.5,1),0) -> 0 | M19: =MAX(MIN($K19-M$3*0.5,1),0) -> 0 | N19: =MAX(MIN($K19-N$3*0.5,1),0) -> 0 | O19: =MAX(MIN($K19-O$3*0.5,1),0) -> 0 | P19: =MAX(MIN($K19-P$3*0.5,1),0) -> 0 | Q19: =MAX(MIN($K19-Q$3*0.5,1),0) -> 0 | R19: =MAX(MIN($K19-R$3*0.5,1),0) -> 0 | S19: =MAX(MIN($K19-S$3*0.5,1),0) -> 0 | ... AY19: =MAX(MIN($K19-AY$3*0.5,1),0) -> 0
H20: 17 | I20: =COUNTIF($C$4:$C$16,H20) -> 0 | J20: =COUNTIF($E$4:$E$16,H20) -> 0 | K20: 0 | L20: =MAX(MIN($K20-L$3*0.5,1),0) -> 0 | M20: =MAX(MIN($K20-M$3*0.5,1),0) -> 0 | N20: =MAX(MIN($K20-N$3*0.5,1),0) -> 0 | O20: =MAX(MIN($K20-O$3*0.5,1),0) -> 0 | P20: =MAX(MIN($K20-P$3*0.5,1),0) -> 0 | Q20: =MAX(MIN($K20-Q$3*0.5,1),0) -> 0 | R20: =MAX(MIN($K20-R$3*0.5,1),0) -> 0 | S20: =MAX(MIN($K20-S$3*0.5,1),0) -> 0 | ... AY20: =MAX(MIN($K20-AY$3*0.5,1),0) -> 0
H21: 18 | I21: =COUNTIF($C$4:$C$16,H21) -> 0 | J21: =COUNTIF($E$4:$E$16,H21) -> 0 | K21: 0 | L21: =MAX(MIN($K21-L$3*0.5,1),0) -> 0 | M21: =MAX(MIN($K21-M$3*0.5,1),0) -> 0 | N21: =MAX(MIN($K21-N$3*0.5,1),0) -> 0 | O21: =MAX(MIN($K21-O$3*0.5,1),0) -> 0 | P21: =MAX(MIN($K21-P$3*0.5,1),0) -> 0 | Q21: =MAX(MIN($K21-Q$3*0.5,1),0) -> 0 | R21: =MAX(MIN($K21-R$3*0.5,1),0) -> 0 | S21: =MAX(MIN($K21-S$3*0.5,1),0) -> 0 | ... AY21: =MAX(MIN($K21-AY$3*0.5,1),0) -> 0
H22: 19 | I22: =COUNTIF($C$4:$C$16,H22) -> 3 | J22: =COUNTIF($E$4:$E$16,H22) -> 0 | K22: 12.46 | L22: =MAX(MIN($K22-L$3*0.5,1),0) -> 1 | M22: =MAX(MIN($K22-M$3*0.5,1),0) -> 1 | N22: =MAX(MIN($K22-N$3*0.5,1),0) -> 1 | O22: =MAX(MIN($K22-O$3*0.5,1),0) -> 1 | P22: =MAX(MIN($K22-P$3*0.5,1),0) -> 1 | Q22: =MAX(MIN($K22-Q$3*0.5,1),0) -> 1 | R22: =MAX(MIN($K22-R$3*0.5,1),0) -> 1 | S22: =MAX(MIN($K22-S$3*0.5,1),0) -> 1 | ... AY22: =MAX(MIN($K22-AY$3*0.5,1),0) -> 0
H23: 20 | I23: =COUNTIF($C$4:$C$16,H23) -> 0 | J23: =COUNTIF($E$4:$E$16,H23) -> 1 | K23: 3.64 | L23: =MAX(MIN($K23-L$3*0.5,1),0) -> 1 | M23: =MAX(MIN($K23-M$3*0.5,1),0) -> 1 | N23: =MAX(MIN($K23-N$3*0.5,1),0) -> 1 | O23: =MAX(MIN($K23-O$3*0.5,1),0) -> 1 | P23: =MAX(MIN($K23-P$3*0.5,1),0) -> 1 | Q23: =MAX(MIN($K23-Q$3*0.5,1),0) -> 0.64 | R23: =MAX(MIN($K23-R$3*0.5,1),0) -> 0.14 | S23: =MAX(MIN($K23-S$3*0.5,1),0) -> 0 | ... AY23: =MAX(MIN($K23-AY$3*0.5,1),0) -> 0
H24: 21 | I24: =COUNTIF($C$4:$C$16,H24) -> 2 | J24: =COUNTIF($E$4:$E$16,H24) -> 0 | K24: 7.9 | L24: =MAX(MIN($K24-L$3*0.5,1),0) -> 1 | M24: =MAX(MIN($K24-M$3*0.5,1),0) -> 1 | N24: =MAX(MIN($K24-N$3*0.5,1),0) -> 1 | O24: =MAX(MIN($K24-O$3*0.5,1),0) -> 1 | P24: =MAX(MIN($K24-P$3*0.5,1),0) -> 1 | Q24: =MAX(MIN($K24-Q$3*0.5,1),0) -> 1 | R24: =MAX(MIN($K24-R$3*0.5,1),0) -> 1 | S24: =MAX(MIN($K24-S$3*0.5,1),0) -> 1 | ... AY24: =MAX(MIN($K24-AY$3*0.5,1),0) -> 0
H25: 22 | I25: =COUNTIF($C$4:$C$16,H25) -> 0 | J25: =COUNTIF($E$4:$E$16,H25) -> 0 | K25: 0 | L25: =MAX(MIN($K25-L$3*0.5,1),0) -> 0 | M25: =MAX(MIN($K25-M$3*0.5,1),0) -> 0 | N25: =MAX(MIN($K25-N$3*0.5,1),0) -> 0 | O25: =MAX(MIN($K25-O$3*0.5,1),0) -> 0 | P25: =MAX(MIN($K25-P$3*0.5,1),0) -> 0 | Q25: =MAX(MIN($K25-Q$3*0.5,1),0) -> 0 | R25: =MAX(MIN($K25-R$3*0.5,1),0) -> 0 | S25: =MAX(MIN($K25-S$3*0.5,1),0) -> 0 | ... AY25: =MAX(MIN($K25-AY$3*0.5,1),0) -> 0
H26: Total | I26: =SUM(I4:I25)+SUM(J4:J25) -> 26
I27: Diff | L27: Drops
H28: Arcana | I28: % | L28: 1 | M28: 2 | N28: 3 | O28: 4 | P28: 5 | Q28: 6 | R28: 7 | S28: 8 | T28: 9 | U28: 10 | V28: 11 | W28: 12 | X28: 13 | Y28: 14 | Z28: 15 | AA28: 16 | AB28: 17 | AC28: 18 | AD28: 19 | AE28: 20 | AF28: 21 | AG28: 22 | AH28: 23 | AI28: 24 | AJ28: 25 | AK28: 26 | AL28: 27 | AM28: 28 | AN28: 29 | AO28: 30 | AP28: 31 | AQ28: 32 | AR28: 33 | AS28: 34 | AT28: 35 | AU28: 36 | AV28: 37 | AW28: 38 | AX28: 39 | AY28: 40
H29: 1 | I29: =K4-Total!D4 -> -3.04 | L29: =MAX(MIN($I29-L$28*0.5,1),0) -> 0 | M29: =MAX(MIN($I29-M$28*0.5,1),0) -> 0 | N29: =MAX(MIN($I29-N$28*0.5,1),0) -> 0 | O29: =MAX(MIN($I29-O$28*0.5,1),0) -> 0 | P29: =MAX(MIN($I29-P$28*0.5,1),0) -> 0 | Q29: =MAX(MIN($I29-Q$28*0.5,1),0) -> 0 | R29: =MAX(MIN($I29-R$28*0.5,1),0) -> 0 | S29: =MAX(MIN($I29-S$28*0.5,1),0) -> 0 | ... AY29: =MAX(MIN($I29-AY$28*0.5,1),0) -> 0
H30: 2 | I30: =K5-Total!D5 -> -2.34 | L30: =MAX(MIN($I30-L$28*0.5,1),0) -> 0 | M30: =MAX(MIN($I30-M$28*0.5,1),0) -> 0 | N30: =MAX(MIN($I30-N$28*0.5,1),0) -> 0 | O30: =MAX(MIN($I30-O$28*0.5,1),0) -> 0 | P30: =MAX(MIN($I30-P$28*0.5,1),0) -> 0 | Q30: =MAX(MIN($I30-Q$28*0.5,1),0) -> 0 | R30: =MAX(MIN($I30-R$28*0.5,1),0) -> 0 | S30: =MAX(MIN($I30-S$28*0.5,1),0) -> 0 | ... AY30: =MAX(MIN($I30-AY$28*0.5,1),0) -> 0
H31: 3 | I31: =K6-Total!D6 -> 4.66 | L31: =MAX(MIN($I31-L$28*0.5,1),0) -> 1 | M31: =MAX(MIN($I31-M$28*0.5,1),0) -> 1 | N31: =MAX(MIN($I31-N$28*0.5,1),0) -> 1 | O31: =MAX(MIN($I31-O$28*0.5,1),0) -> 1 | P31: =MAX(MIN($I31-P$28*0.5,1),0) -> 1 | Q31: =MAX(MIN($I31-Q$28*0.5,1),0) -> 1 | R31: =MAX(MIN($I31-R$28*0.5,1),0) -> 1 | S31: =MAX(MIN($I31-S$28*0.5,1),0) -> 0.66 | ... AY31: =MAX(MIN($I31-AY$28*0.5,1),0) -> 0
H32: 4 | I32: =K7-Total!D7 -> -0.01 | L32: =MAX(MIN($I32-L$28*0.5,1),0) -> 0 | M32: =MAX(MIN($I32-M$28*0.5,1),0) -> 0 | N32: =MAX(MIN($I32-N$28*0.5,1),0) -> 0 | O32: =MAX(MIN($I32-O$28*0.5,1),0) -> 0 | P32: =MAX(MIN($I32-P$28*0.5,1),0) -> 0 | Q32: =MAX(MIN($I32-Q$28*0.5,1),0) -> 0 | R32: =MAX(MIN($I32-R$28*0.5,1),0) -> 0 | S32: =MAX(MIN($I32-S$28*0.5,1),0) -> 0 | ... AY32: =MAX(MIN($I32-AY$28*0.5,1),0) -> 0
H33: 5 | I33: =K8-Total!D8 -> 4.25 | L33: =MAX(MIN($I33-L$28*0.5,1),0) -> 1 | M33: =MAX(MIN($I33-M$28*0.5,1),0) -> 1 | N33: =MAX(MIN($I33-N$28*0.5,1),0) -> 1 | O33: =MAX(MIN($I33-O$28*0.5,1),0) -> 1 | P33: =MAX(MIN($I33-P$28*0.5,1),0) -> 1 | Q33: =MAX(MIN($I33-Q$28*0.5,1),0) -> 1 | R33: =MAX(MIN($I33-R$28*0.5,1),0) -> 0.75 | S33: =MAX(MIN($I33-S$28*0.5,1),0) -> 0.25 | ... AY33: =MAX(MIN($I33-AY$28*0.5,1),0) -> 0
H34: 6 | I34: =K9-Total!D9 -> 1.59 | L34: =MAX(MIN($I34-L$28*0.5,1),0) -> 1 | M34: =MAX(MIN($I34-M$28*0.5,1),0) -> 0.59 | N34: =MAX(MIN($I34-N$28*0.5,1),0) -> 0.09 | O34: =MAX(MIN($I34-O$28*0.5,1),0) -> 0 | P34: =MAX(MIN($I34-P$28*0.5,1),0) -> 0 | Q34: =MAX(MIN($I34-Q$28*0.5,1),0) -> 0 | R34: =MAX(MIN($I34-R$28*0.5,1),0) -> 0 | S34: =MAX(MIN($I34-S$28*0.5,1),0) -> 0 | ... AY34: =MAX(MIN($I34-AY$28*0.5,1),0) -> 0
H35: 7 | I35: =K10-Total!D10 -> 6.35 | L35: =MAX(MIN($I35-L$28*0.5,1),0) -> 1 | M35: =MAX(MIN($I35-M$28*0.5,1),0) -> 1 | N35: =MAX(MIN($I35-N$28*0.5,1),0) -> 1 | O35: =MAX(MIN($I35-O$28*0.5,1),0) -> 1 | P35: =MAX(MIN($I35-P$28*0.5,1),0) -> 1 | Q35: =MAX(MIN($I35-Q$28*0.5,1),0) -> 1 | R35: =MAX(MIN($I35-R$28*0.5,1),0) -> 1 | S35: =MAX(MIN($I35-S$28*0.5,1),0) -> 1 | ... AY35: =MAX(MIN($I35-AY$28*0.5,1),0) -> 0
H36: 8 | I36: =K11-Total!D11 -> 3.66 | L36: =MAX(MIN($I36-L$28*0.5,1),0) -> 1 | M36: =MAX(MIN($I36-M$28*0.5,1),0) -> 1 | N36: =MAX(MIN($I36-N$28*0.5,1),0) -> 1 | O36: =MAX(MIN($I36-O$28*0.5,1),0) -> 1 | P36: =MAX(MIN($I36-P$28*0.5,1),0) -> 1 | Q36: =MAX(MIN($I36-Q$28*0.5,1),0) -> 0.66 | R36: =MAX(MIN($I36-R$28*0.5,1),0) -> 0.16 | S36: =MAX(MIN($I36-S$28*0.5,1),0) -> 0 | ... AY36: =MAX(MIN($I36-AY$28*0.5,1),0) -> 0
H37: 9 | I37: =K12-Total!D12 -> -2.4 | L37: =MAX(MIN($I37-L$28*0.5,1),0) -> 0 | M37: =MAX(MIN($I37-M$28*0.5,1),0) -> 0 | N37: =MAX(MIN($I37-N$28*0.5,1),0) -> 0 | O37: =MAX(MIN($I37-O$28*0.5,1),0) -> 0 | P37: =MAX(MIN($I37-P$28*0.5,1),0) -> 0 | Q37: =MAX(MIN($I37-Q$28*0.5,1),0) -> 0 | R37: =MAX(MIN($I37-R$28*0.5,1),0) -> 0 | S37: =MAX(MIN($I37-S$28*0.5,1),0) -> 0 | ... AY37: =MAX(MIN($I37-AY$28*0.5,1),0) -> 0
H38: 10 | I38: =K13-Total!D13 -> 1.35 | L38: =MAX(MIN($I38-L$28*0.5,1),0) -> 0.85 | M38: =MAX(MIN($I38-M$28*0.5,1),0) -> 0.35 | N38: =MAX(MIN($I38-N$28*0.5,1),0) -> 0 | O38: =MAX(MIN($I38-O$28*0.5,1),0) -> 0 | P38: =MAX(MIN($I38-P$28*0.5,1),0) -> 0 | Q38: =MAX(MIN($I38-Q$28*0.5,1),0) -> 0 | R38: =MAX(MIN($I38-R$28*0.5,1),0) -> 0 | S38: =MAX(MIN($I38-S$28*0.5,1),0) -> 0 | ... AY38: =MAX(MIN($I38-AY$28*0.5,1),0) -> 0
H39: 11 | I39: =K14-Total!D14 -> -6.78 | L39: =MAX(MIN($I39-L$28*0.5,1),0) -> 0 | M39: =MAX(MIN($I39-M$28*0.5,1),0) -> 0 | N39: =MAX(MIN($I39-N$28*0.5,1),0) -> 0 | O39: =MAX(MIN($I39-O$28*0.5,1),0) -> 0 | P39: =MAX(MIN($I39-P$28*0.5,1),0) -> 0 | Q39: =MAX(MIN($I39-Q$28*0.5,1),0) -> 0 | R39: =MAX(MIN($I39-R$28*0.5,1),0) -> 0 | S39: =MAX(MIN($I39-S$28*0.5,1),0) -> 0 | ... AY39: =MAX(MIN($I39-AY$28*0.5,1),0) -> 0
H40: 12 | I40: =K15-Total!D15 -> -0.6 | L40: =MAX(MIN($I40-L$28*0.5,1),0) -> 0 | M40: =MAX(MIN($I40-M$28*0.5,1),0) -> 0 | N40: =MAX(MIN($I40-N$28*0.5,1),0) -> 0 | O40: =MAX(MIN($I40-O$28*0.5,1),0) -> 0 | P40: =MAX(MIN($I40-P$28*0.5,1),0) -> 0 | Q40: =MAX(MIN($I40-Q$28*0.5,1),0) -> 0 | R40: =MAX(MIN($I40-R$28*0.5,1),0) -> 0 | S40: =MAX(MIN($I40-S$28*0.5,1),0) -> 0 | ... AY40: =MAX(MIN($I40-AY$28*0.5,1),0) -> 0
... H50: 22 | I50: =K25-Total!D25 -> -1.19 | L50: =MAX(MIN($I50-L$28*0.5,1),0) -> 0 | M50: =MAX(MIN($I50-M$28*0.5,1),0) -> 0 | N50: =MAX(MIN($I50-N$28*0.5,1),0) -> 0 | O50: =MAX(MIN($I50-O$28*0.5,1),0) -> 0 | P50: =MAX(MIN($I50-P$28*0.5,1),0) -> 0 | Q50: =MAX(MIN($I50-Q$28*0.5,1),0) -> 0 | R50: =MAX(MIN($I50-R$28*0.5,1),0) -> 0 | S50: =MAX(MIN($I50-S$28*0.5,1),0) -> 0 | ... AY50: =MAX(MIN($I50-AY$28*0.5,1),0) -> 0

Sheet Clorinde
I2: Count | L2: Drops
B3: Run | C3: First | E3: Second | H3: Arcana | I3: First | J3: Second | K3: % | L3: 1 | M3: 2 | N3: 3 | O3: 4 | P3: 5 | Q3: 6 | R3: 7 | S3: 8 | T3: 9 | U3: 10 | V3: 11 | W3: 12 | X3: 13 | Y3: 14 | Z3: 15 | AA3: 16 | AB3: 17 | AC3: 18 | AD3: 19 | AE3: 20 | AF3: 21 | AG3: 22 | AH3: 23 | AI3: 24 | AJ3: 25 | AK3: 26 | AL3: 27 | AM3: 28 | AN3: 29 | AO3: 30 | AP3: 31 | AQ3: 32 | AR3: 33 | AS3: 34 | AT3: 35 | AU3: 36 | AV3: 37 | AW3: 38 | AX3: 39 | AY3: 40
B4: 1 | C4: 6 | D4: Lovers | E4: 9 | F4: Heremit | H4: 1 | I4: =COUNTIF($C$4:$C$16,H4) -> 0 | J4: =COUNTIF($E$4:$E$16,H4) -> 1 | K4: 3.68 | L4: =MAX(MIN($K4-L$3*0.5,1),0) -> 1 | M4: =MAX(MIN($K4-M$3*0.5,1),0) -> 1 | N4: =MAX(MIN($K4-N$3*0.5,1),0) -> 1 | O4: =MAX(MIN($K4-O$3*0.5,1),0) -> 1 | P4: =MAX(MIN($K4-P$3*0.5,1),0) -> 1 | Q4: =MAX(MIN($K4-Q$3*0.5,1),0) -> 0.68 | R4: =MAX(MIN($K4-R$3*0.5,1),0) -> 0.18 | S4: =MAX(MIN($K4-S$3*0.5,1),0) -> 0 | ... AY4: =MAX(MIN($K4-AY$3*0.5,1),0) -> 0
B5: 2 | C5: 6 | D5: Chariot | E5: 7 | F5: Lovers | H5: 2 | I5: =COUNTIF($C$4:$C$16,H5) -> 0 | J5: =COUNTIF($E$4:$E$16,H5) -> 2 | K5: 7.35 | L5: =MAX(MIN($K5-L$3*0.5,1),0) -> 1 | M5: =MAX(MIN($K5-M$3*0.5,1),0) -> 1 | N5: =MAX(MIN($K5-N$3*0.5,1),0) -> 1 | O5: =MAX(MIN($K5-O$3*0.5,1),0) -> 1 | P5: =MAX(MIN($K5-P$3*0.5,1),0) -> 1 | Q5: =MAX(MIN($K5-Q$3*0.5,1),0) -> 1 | R5: =MAX(MIN($K5-R$3*0.5,1),0) -> 1 | S5: =MAX(MIN($K5-S$3*0.5,1),0) -> 1 | ... AY5: =MAX(MIN($K5-AY$3*0.5,1),0) -> 0
B6: 3 | C6: 21 | D6: World | E6: 2 | F6: Priestess | H6: 3 | I6: =COUNTIF($C$4:$C$16,H6) -> 0 | J6: =COUNTIF($E$4:$E$16,H6) -> 1 | K6: 3.68 | L6: =MAX(MIN($K6-L$3*0.5,1),0) -> 1 | M6: =MAX(MIN($K6-M$3*0.5,1),0) -> 1 | N6: =MAX(MIN($K6-N$3*0.5,1),0) -> 1 | O6: =MAX(MIN($K6-O$3*0.5,1),0) -> 1 | P6: =MAX(MIN($K6-P$3*0.5,1),0) -> 1 | Q6: =MAX(MIN($K6-Q$3*0.5,1),0) -> 0.68 | R6: =MAX(MIN($K6-R$3*0.5,1),0) -> 0.18 | S6: =MAX(MIN($K6-S$3*0.5,1),0) -> 0 | ... AY6: =MAX(MIN($K6-AY$3*0.5,1),0) -> 0
B7: 4 | C7: 21 | D7: World | E7: 9 | F7: Heremit | H7: 4 | I7: =COUNTIF($C$4:$C$16,H7) -> 0 | J7: =COUNTIF($E$4:$E$16,H7) -> 0 | K7: 0 | L7: =MAX(MIN($K7-L$3*0.5,1),0) -> 0 | M7: =MAX(MIN($K7-M$3*0.5,1),0) -> 0 | N7: =MAX(MIN($K7-N$3*0.5,1),0) -> 0 | O7: =MAX(MIN($K7-O$3*0.5,1),0) -> 0 | P7: =MAX(MIN($K7-P$3*0.5,1),0) -> 0 | Q7: =MAX(MIN($K7-Q$3*0.5,1),0) -> 0 | R7: =MAX(MIN($K7-R$3*0.5,1),0) -> 0 | S7: =MAX(MIN($K7-S$3*0.5,1),0) -> 0 | ... AY7: =MAX(MIN($K7-AY$3*0.5,1),0) -> 0
B8: 5 | C8: 15 | D8: Devil | E8: 11 | F8: Justice | H8: 5 | I8: =COUNTIF($C$4:$C$16,H8) -> 1 | J8: =COUNTIF($E$4:$E$16,H8) -> 0 | K8: 3.82 | L8: =MAX(MIN($K8-L$3*0.5,1),0) -> 1 | M8: =MAX(MIN($K8-M$3*0.5,1),0) -> 1 | N8: =MAX(MIN($K8-N$3*0.5,1),0) -> 1 | O8: =MAX(MIN($K8-O$3*0.5,1),0) -> 1 | P8: =MAX(MIN($K8-P$3*0.5,1),0) -> 1 | Q8: =MAX(MIN($K8-Q$3*0.5,1),0) -> 0.82 | R8: =MAX(MIN($K8-R$3*0.5,1),0) -> 0.32 | S8: =MAX(MIN($K8-S$3*0.5,1),0) -> 0 | ... AY8: =MAX(MIN($K8-AY$3*0.5,1),0) -> 0
B9: 6 | C9: 21 | D9: World | E9: 16 | F9: Tower | H9: 6 | I9: =COUNTIF($C$4:$C$16,H9) -> 3 | J9: =COUNTIF($E$4:$E$16,H9) -> 0 | K9: 12.03 | L9: =MAX(MIN($K9-L$3*0.5,1),0) -> 1 | M9: =MAX(MIN($K9-M$3*0.5,1),0) -> 1 | N9: =MAX(MIN($K9-N$3*0.5,1),0) -> 1 | O9: =MAX(MIN($K9-O$3*0.5,1),0) -> 1 | P9: =MAX(MIN($K9-P$3*0.5,1),0) -> 1 | Q9: =MAX(MIN($K9-Q$3*0.5,1),0) -> 1 | R9: =MAX(MIN($K9-R$3*0.5,1),0) -> 1 | S9: =MAX(MIN($K9-S$3*0.5,1),0) -> 1 | ... AY9: =MAX(MIN($K9-AY$3*0.5,1),0) -> 0
B10: 7 | C10: 8 | D10: Strength | E10: 18 | F10: Moon | H10: 7 | I10: =COUNTIF($C$4:$C$16,H10) -> 1 | J10: =COUNTIF($E$4:$E$16,H10) -> 1 | K10: 7.99 | L10: =MAX(MIN($K10-L$3*0.5,1),0) -> 1 | M10: =MAX(MIN($K10-M$3*0.5,1),0) -> 1 | N10: =MAX(MIN($K10-N$3*0.5,1),0) -> 1 | O10: =MAX(MIN($K10-O$3*0.5,1),0) -> 1 | P10: =MAX(MIN($K10-P$3*0.5,1),0) -> 1 | Q10: =MAX(MIN($K10-Q$3*0.5,1),0) -> 1 | R10: =MAX(MIN($K10-R$3*0.5,1),0) -> 1 | S10: =MAX(MIN($K10-S$3*0.5,1),0) -> 1 | ... AY10: =MAX(MIN($K10-AY$3*0.5,1),0) -> 0
B11: 8 | C11: 5 | D11: Hierophant | E11: 17 | F11: Star | H11: 8 | I11: =COUNTIF($C$4:$C$16,H11) -> 1 | J11: =COUNTIF($E$4:$E$16,H11) -> 1 | K11: 7.66 | L11: =MAX(MIN($K11-L$3*0.5,1),0) -> 1 | M11: =MAX(MIN($K11-M$3*0.5,1),0) -> 1 | N11: =MAX(MIN($K11-N$3*0.5,1),0) -> 1 | O11: =MAX(MIN($K11-O$3*0.5,1),0) -> 1 | P11: =MAX(MIN($K11-P$3*0.5,1),0) -> 1 | Q11: =MAX(MIN($K11-Q$3*0.5,1),0) -> 1 | R11: =MAX(MIN($K11-R$3*0.5,1),0) -> 1 | S11: =MAX(MIN($K11-S$3*0.5,1),0) -> 1 | ... AY11: =MAX(MIN($K11-AY$3*0.5,1),0) -> 0
B12: 9 | C12: 20 | D12: Judgment | E12: 1 | F12: Magician | H12: 9 | I12: =COUNTIF($C$4:$C$16,H12) -> 0 | J12: =COUNTIF($E$4:$E$16,H12) -> 2 | K12: 7.35 | L12: =MAX(MIN($K12-L$3*0.5,1),0) -> 1 | M12: =MAX(MIN($K12-M$3*0.5,1),0) -> 1 | N12: =MAX(MIN($K12-N$3*0.5,1),0) -> 1 | O12: =MAX(MIN($K12-O$3*0.5,1),0) -> 1 | P12: =MAX(MIN($K12-P$3*0.5,1),0) -> 1 | Q12: =MAX(MIN($K12-Q$3*0.5,1),0) -> 1 | R12: =MAX(MIN($K12-R$3*0.5,1),0) -> 1 | S12: =MAX(MIN($K12-S$3*0.5,1),0) -> 1 | ... AY12: =MAX(MIN($K12-AY$3*0.5,1),0) -> 0
B13: 10 | C13: 6 | D13: Lovers | E13: 18 | F13: Moon | H13: 10 | I13: =COUNTIF($C$4:$C$16,H13) -> 1 | J13: =COUNTIF($E$4:$E$16,H13) -> 0 | K13: 3.82 | L13: =MAX(MIN($K13-L$3*0.5,1),0) -> 1 | M13: =MAX(MIN($K13-M$3*0.5,1),0) -> 1 | N13: =MAX(MIN($K13-N$3*0.5,1),0) -> 1 | O13: =MAX(MIN($K13-O$3*0.5,1),0) -> 1 | P13: =MAX(MIN($K13-P$3*0.5,1),0) -> 1 | Q13: =MAX(MIN($K13-Q$3*0.5,1),0) -> 0.82 | R13: =MAX(MIN($K13-R$3*0.5,1),0) -> 0.32 | S13: =MAX(MIN($K13-S$3*0.5,1),0) -> 0 | ... AY13: =MAX(MIN($K13-AY$3*0.5,1),0) -> 0
B14: 11 | C14: 10 | D14: Wheel | E14: 2 | F14: Priestess | H14: 11 | I14: =COUNTIF($C$4:$C$16,H14) -> 0 | J14: =COUNTIF($E$4:$E$16,H14) -> 1 | K14: 3.68 | L14: =MAX(MIN($K14-L$3*0.5,1),0) -> 1 | M14: =MAX(MIN($K14-M$3*0.5,1),0) -> 1 | N14: =MAX(MIN($K14-N$3*0.5,1),0) -> 1 | O14: =MAX(MIN($K14-O$3*0.5,1),0) -> 1 | P14: =MAX(MIN($K14-P$3*0.5,1),0) -> 1 | Q14: =MAX(MIN($K14-Q$3*0.5,1),0) -> 0.68 | R14: =MAX(MIN($K14-R$3*0.5,1),0) -> 0.18 | S14: =MAX(MIN($K14-S$3*0.5,1),0) -> 0 | ... AY14: =MAX(MIN($K14-AY$3*0.5,1),0) -> 0
B15: 12 | C15: 16 | D15: Tower | E15: 8 | F15: Strength | H15: 12 | I15: =COUNTIF($C$4:$C$16,H15) -> 0 | J15: =COUNTIF($E$4:$E$16,H15) -> 0 | K15: 0 | L15: =MAX(MIN($K15-L$3*0.5,1),0) -> 0 | M15: =MAX(MIN($K15-M$3*0.5,1),0) -> 0 | N15: =MAX(MIN($K15-N$3*0.5,1),0) -> 0 | O15: =MAX(MIN($K15-O$3*0.5,1),0) -> 0 | P15: =MAX(MIN($K15-P$3*0.5,1),0) -> 0 | Q15: =MAX(MIN($K15-Q$3*0.5,1),0) -> 0 | R15: =MAX(MIN($K15-R$3*0.5,1),0) -> 0 | S15: =MAX(MIN($K15-S$3*0.5,1),0) -> 0 | ... AY15: =MAX(MIN($K15-AY$3*0.5,1),0) -> 0
B16: 13 | C16: 7 | D16: Chariot | E16: 3 | F16: Empress | H16: 13 | I16: =COUNTIF($C$4:$C$16,H16) -> 0 | J16: =COUNTIF($E$4:$E$16,H16) -> 0 | K16: 0 | L16: =MAX(MIN($K16-L$3*0.5,1),0) -> 0 | M16: =MAX(MIN($K16-M$3*0.5,1),0) -> 0 | N16: =MAX(MIN($K16-N$3*0.5,1),0) -> 0 | O16: =MAX(MIN($K16-O$3*0.5,1),0) -> 0 | P16: =MAX(MIN($K16-P$3*0.5,1),0) -> 0 | Q16: =MAX(MIN($K16-Q$3*0.5,1),0) -> 0 | R16: =MAX(MIN($K16-R$3*0.5,1),0) -> 0 | S16: =MAX(MIN($K16-S$3*0.5,1),0) -> 0 | ... AY16: =MAX(MIN($K16-AY$3*0.5,1),0) -> 0
H17: 14 | I17: =COUNTIF($C$4:$C$16,H17) -> 0 | J17: =COUNTIF($E$4:$E$16,H17) -> 0 | K17: 0 | L17: =MAX(MIN($K17-L$3*0.5,1),0) -> 0 | M17: =MAX(MIN($K17-M$3*0.5,1),0) -> 0 | N17: =MAX(MIN($K17-N$3*0.5,1),0) -> 0 | O17: =MAX(MIN($K17-O$3*0.5,1),0) -> 0 | P17: =MAX(MIN($K17-P$3*0.5,1),0) -> 0 | Q17: =MAX(MIN($K17-Q$3*0.5,1),0) -> 0 | R17: =MAX(MIN($K17-R$3*0.5,1),0) -> 0 | S17: =MAX(MIN($K17-S$3*0.5,1),0) -> 0 | ... AY17: =MAX(MIN($K17-AY$3*0.5,1),0) -> 0
H18: 15 | I18: =COUNTIF($C$4:$C$16,H18) -> 1 | J18: =COUNTIF($E$4:$E$16,H18) -> 0 | K18: 3.82 | L18: =MAX(MIN($K18-L$3*0.5,1),0) -> 1 | M18: =MAX(MIN($K18-M$3*0.5,1),0) -> 1 | N18: =MAX(MIN($K18-N$3*0.5,1),0) -> 1 | O18: =MAX(MIN($K18-O$3*0.5,1),0) -> 1 | P18: =MAX(MIN($K18-P$3*0.5,1),0) -> 1 | Q18: =MAX(MIN($K18-Q$3*0.5,1),0) -> 0.82 | R18: =MAX(MIN($K18-R$3*0.5,1),0) -> 0.32 | S18: =MAX(MIN($K18-S$3*0.5,1),0) -> 0 | ... AY18: =MAX(MIN($K18-AY$3*0.5,1),0) -> 0
H19: 16 | I19: =COUNTIF($C$4:$C$16,H19) -> 1 | J19: =COUNTIF($E$4:$E$16,H19) -> 1 | K19: 7.66 | L19: =MAX(MIN($K19-L$3*0.5,1),0) -> 1 | M19: =MAX(MIN($K19-M$3*0.5,1),0) -> 1 | N19: =MAX(MIN($K19-N$3*0.5,1),0) -> 1 | O19: =MAX(MIN($K19-O$3*0.5,1),0) -> 1 | P19: =MAX(MIN($K19-P$3*0.5,1),0) -> 1 | Q19: =MAX(MIN($K19-Q$3*0.5,1),0) -> 1 | R19: =MAX(MIN($K19-R$3*0.5,1),0) -> 1 | S19: =MAX(MIN($K19-S$3*0.5,1),0) -> 1 | ... AY19: =MAX(MIN($K19-AY$3*0.5,1),0) -> 0
H20: 17 | I20: =COUNTIF($C$4:$C$16,H20) -> 0 | J20: =COUNTIF($E$4:$E$16,H20) -> 1 | K20: 3.68 | L20: =MAX(MIN($K20-L$3*0.5,1),0) -> 1 | M20: =MAX(MIN($K20-M$3*0.5,1),0) -> 1 | N20: =MAX(MIN($K20-N$3*0.5,1),0) -> 1 | O20: =MAX(MIN($K20-O$3*0.5,1),0) -> 1 | P20: =MAX(MIN($K20-P$3*0.5,1),0) -> 1 | Q20: =MAX(MIN($K20-Q$3*0.5,1),0) -> 0.68 | R20: =MAX(MIN($K20-R$3*0.5,1),0) -> 0.18 | S20: =MAX(MIN($K20-S$3*0.5,1),0) -> 0 | ... AY20: =MAX(MIN($K20-AY$3*0.5,1),0) -> 0
H21: 18 | I21: =COUNTIF($C$4:$C$16,H21) -> 0 | J21: =COUNTIF($E$4:$E$16,H21) -> 2 | K21: 7.35 | L21: =MAX(MIN($K21-L$3*0.5,1),0) -> 1 | M21: =MAX(MIN($K21-M$3*0.5,1),0) -> 1 | N21: =MAX(MIN($K21-N$3*0.5,1),0) -> 1 | O21: =MAX(MIN($K21-O$3*0.5,1),0) -> 1 | P21: =MAX(MIN($K21-P$3*0.5,1),0) -> 1 | Q21: =MAX(MIN($K21-Q$3*0.5,1),0) -> 1 | R21: =MAX(MIN($K21-R$3*0.5,1),0) -> 1 | S21: =MAX(MIN($K21-S$3*0.5,1),0) -> 1 | ... AY21: =MAX(MIN($K21-AY$3*0.5,1),0) -> 0
H22: 19 | I22: =COUNTIF($C$4:$C$16,H22) -> 0 | J22: =COUNTIF($E$4:$E$16,H22) -> 0 | K22: 0 | L22: =MAX(MIN($K22-L$3*0.5,1),0) -> 0 | M22: =MAX(MIN($K22-M$3*0.5,1),0) -> 0 | N22: =MAX(MIN($K22-N$3*0.5,1),0) -> 0 | O22: =MAX(MIN($K22-O$3*0.5,1),0) -> 0 | P22: =MAX(MIN($K22-P$3*0.5,1),0) -> 0 | Q22: =MAX(MIN($K22-Q$3*0.5,1),0) -> 0 | R22: =MAX(MIN($K22-R$3*0.5,1),0) -> 0 | S22: =MAX(MIN($K22-S$3*0.5,1),0) -> 0 | ... AY22: =MAX(MIN($K22-AY$3*0.5,1),0) -> 0
H23: 20 | I23: =COUNTIF($C$4:$C$16,H23) -> 1 | J23: =COUNTIF($E$4:$E$16,H23) -> 0 | K23: 3.82 | L23: =MAX(MIN($K23-L$3*0.5,1),0) -> 1 | M23: =MAX(MIN($K23-M$3*0.5,1),0) -> 1 | N23: =MAX(MIN($K23-N$3*0.5,1),0) -> 1 | O23: =MAX(MIN($K23-O$3*0.5,1),0) -> 1 | P23: =MAX(MIN($K23-P$3*0.5,1),0) -> 1 | Q23: =MAX(MIN($K23-Q$3*0.5,1),0) -> 0.82 | R23: =MAX(MIN($K23-R$3*0.5,1),0) -> 0.32 | S23: =MAX(MIN($K23-S$3*0.5,1),0) -> 0 | ... AY23: =MAX(MIN($K23-AY$3*0.5,1),0) -> 0
H24: 21 | I24: =COUNTIF($C$4:$C$16,H24) -> 3 | J24: =COUNTIF($E$4:$E$16,H24) -> 0 | K24: 12.61 | L24: =MAX(MIN($K24-L$3*0.5,1),0) -> 1 | M24: =MAX(MIN($K24-M$3*0.5,1),0) -> 1 | N24: =MAX(MIN($K24-N$3*0.5,1),0) -> 1 | O24: =MAX(MIN($K24-O$3*0.5,1),0) -> 1 | P24: =MAX(MIN($K24-P$3*0.5,1),0) -> 1 | Q24: =MAX(MIN($K24-Q$3*0.5,1),0) -> 1 | R24: =MAX(MIN($K24-R$3*0.5,1),0) -> 1 | S24: =MAX(MIN($K24-S$3*0.5,1),0) -> 1 | ... AY24: =MAX(MIN($K24-AY$3*0.5,1),0) -> 0
H25: 22 | I25: =COUNTIF($C$4:$C$16,H25) -> 0 | J25: =COUNTIF($E$4:$E$16,H25) -> 0 | K25: 0 | L25: =MAX(MIN($K25-L$3*0.5,1),0) -> 0 | M25: =MAX(MIN($K25-M$3*0.5,1),0) -> 0 | N25: =MAX(MIN($K25-N$3*0.5,1),0) -> 0 | O25: =MAX(MIN($K25-O$3*0.5,1),0) -> 0 | P25: =MAX(MIN($K25-P$3*0.5,1),0) -> 0 | Q25: =MAX(MIN($K25-Q$3*0.5,1),0) -> 0 | R25: =MAX(MIN($K25-R$3*0.5,1),0) -> 0 | S25: =MAX(MIN($K25-S$3*0.5,1),0) -> 0 | ... AY25: =MAX(MIN($K25-AY$3*0.5,1),0) -> 0
H26: Total | I26: =SUM(I4:I25)+SUM(J4:J25) -> 26
I27: Diff | L27: Drops
H28: Arcana | I28: % | L28: 1 | M28: 2 | N28: 3 | O28: 4 | P28: 5 | Q28: 6 | R28: 7 | S28: 8 | T28: 9 | U28: 10 | V28: 11 | W28: 12 | X28: 13 | Y28: 14 | Z28: 15 | AA28: 16 | AB28: 17 | AC28: 18 | AD28: 19 | AE28: 20 | AF28: 21 | AG28: 22 | AH28: 23 | AI28: 24 | AJ28: 25 | AK28: 26 | AL28: 27 | AM28: 28 | AN28: 29 | AO28: 30 | AP28: 31 | AQ28: 32 | AR28: 33 | AS28: 34 | AT28: 35 | AU28: 36 | AV28: 37 | AW28: 38 | AX28: 39 | AY28: 40
H29: 1 | I29: =K4-Total!D4 -> 0.64 | L29: =MAX(MIN($I29-L$28*0.5,1),0) -> 0.14 | M29: =MAX(MIN($I29-M$28*0.5,1),0) -> 0 | N29: =MAX(MIN($I29-N$28*0.5,1),0) -> 0 | O29: =MAX(MIN($I29-O$28*0.5,1),0) -> 0 | P29: =MAX(MIN($I29-P$28*0.5,1),0) -> 0 | Q29: =MAX(MIN($I29-Q$28*0.5,1),0) -> 0 | R29: =MAX(MIN($I29-R$28*0.5,1),0) -> 0 | S29: =MAX(MIN($I29-S$28*0.5,1),0) -> 0 | ... AY29: =MAX(MIN($I29-AY$28*0.5,1),0) -> 0
H30: 2 | I30: =K5-Total!D5 -> 1.23 | L30: =MAX(MIN($I30-L$28*0.5,1),0) -> 0.73 | M30: =MAX(MIN($I30-M$28*0.5,1),0) -> 0.23 | N30: =MAX(MIN($I30-N$28*0.5,1),0) -> 0 | O30: =MAX(MIN($I30-O$28*0.5,1),0) -> 0 | P30: =MAX(MIN($I30-P$28*0.5,1),0) -> 0 | Q30: =MAX(MIN($I30-Q$28*0.5,1),0) -> 0 | R30: =MAX(MIN($I30-R$28*0.5,1),0) -> 0 | S30: =MAX(MIN($I30-S$28*0.5,1),0) -> 0 | ... AY30: =MAX(MIN($I30-AY$28*0.5,1),0) -> 0
H31: 3 | I31: =K6-Total!D6 -> -3.05 | L31: =MAX(MIN($I31-L$28*0.5,1),0) -> 0 | M31: =MAX(MIN($I31-M$28*0.5,1),0) -> 0 | N31: =MAX(MIN($I31-N$28*0.5,1),0) -> 0 | O31: =MAX(MIN($I31-O$28*0.5,1),0) -> 0 | P31: =MAX(MIN($I31-P$28*0.5,1),0) -> 0 | Q31: =MAX(MIN($I31-Q$28*0.5,1),0) -> 0 | R31: =MAX(MIN($I31-R$28*0.5,1),0) -> 0 | S31: =MAX(MIN($I31-S$28*0.5,1),0) -> 0 | ... AY31: =MAX(MIN($I31-AY$28*0.5,1),0) -> 0
H32: 4 | I32: =K7-Total!D7 -> -3.65 | L32: =MAX(MIN($I32-L$28*0.5,1),0) -> 0 | M32: =MAX(MIN($I32-M$28*0.5,1),0) -> 0 | N32: =MAX(MIN($I32-N$28*0.5,1),0) -> 0 | O32: =MAX(MIN($I32-O$28*0.5,1),0) -> 0 | P32: =MAX(MIN($I32-P$28*0.5,1),0) -> 0 | Q32: =MAX(MIN($I32-Q$28*0.5,1),0) -> 0 | R32: =MAX(MIN($I32-R$28*0.5,1),0) -> 0 | S32: =MAX(MIN($I32-S$28*0.5,1),0) -> 0 | ... AY32: =MAX(MIN($I32-AY$28*0.5,1),0) -> 0
H33: 5 | I33: =K8-Total!D8 -> 0.8 | L33: =MAX(MIN($I33-L$28*0.5,1),0) -> 0.3 | M33: =MAX(MIN($I33-M$28*0.5,1),0) -> 0 | N33: =MAX(MIN($I33-N$28*0.5,1),0) -> 0 | O33: =MAX(MIN($I33-O$28*0.5,1),0) -> 0 | P33: =MAX(MIN($I33-P$28*0.5,1),0) -> 0 | Q33: =MAX(MIN($I33-Q$28*0.5,1),0) -> 0 | R33: =MAX(MIN($I33-R$28*0.5,1),0) -> 0 | S33: =MAX(MIN($I33-S$28*0.5,1),0) -> 0 | ... AY33: =MAX(MIN($I33-AY$28*0.5,1),0) -> 0
H34: 6 | I34: =K9-Total!D9 -> 1.73 | L34: =MAX(MIN($I34-L$28*0.5,1),0) -> 1 | M34: =MAX(MIN($I34-M$28*0.5,1),0) -> 0.73 | N34: =MAX(MIN($I34-N$28*0.5,1),0) -> 0.23 | O34: =MAX(MIN($I34-O$28*0.5,1),0) -> 0 | P34: =MAX(MIN($I34-P$28*0.5,1),0) -> 0 | Q34: =MAX(MIN($I34-Q$28*0.5,1),0) -> 0 | R34: =MAX(MIN($I34-R$28*0.5,1),0) -> 0 | S34: =MAX(MIN($I34-S$28*0.5,1),0) -> 0 | ... AY34: =MAX(MIN($I34-AY$28*0.5,1),0) -> 0
H35: 7 | I35: =K10-Total!D10 -> -1.59 | L35: =MAX(MIN($I35-L$28*0.5,1),0) -> 0 | M35: =MAX(MIN($I35-M$28*0.5,1),0) -> 0 | N35: =MAX(MIN($I35-N$28*0.5,1),0) -> 0 | O35: =MAX(MIN($I35-O$28*0.5,1),0) -> 0 | P35: =MAX(MIN($I35-P$28*0.5,1),0) -> 0 | Q35: =MAX(MIN($I35-Q$28*0.5,1),0) -> 0 | R35: =MAX(MIN($I35-R$28*0.5,1),0) -> 0 | S35: =MAX(MIN($I35-S$28*0.5,1),0) -> 0 | ... AY35: =MAX(MIN($I35-AY$28*0.5,1),0) -> 0
H36: 8 | I36: =K11-Total!D11 -> 0.41 | L36: =MAX(MIN($I36-L$28*0.5,1),0) -> 0 | M36: =MAX(MIN($I36-M$28*0.5,1),0) -> 0 | N36: =MAX(MIN($I36-N$28*0.5,1),0) -> 0 | O36: =MAX(MIN($I36-O$28*0.5,1),0) -> 0 | P36: =MAX(MIN($I36-P$28*0.5,1),0) -> 0 | Q36: =MAX(MIN($I36-Q$28*0.5,1),0) -> 0 | R36: =MAX(MIN($I36-R$28*0.5,1),0) -> 0 | S36: =MAX(MIN($I36-S$28*0.5,1),0) -> 0 | ... AY36: =MAX(MIN($I36-AY$28*0.5,1),0) -> 0
H37: 9 | I37: =K12-Total!D12 -> 4.95 | L37: =MAX(MIN($I37-L$28*0.5,1),0) -> 1 | M37: =MAX(MIN($I37-M$28*0.5,1),0) -> 1 | N37: =MAX(MIN($I37-N$28*0.5,1),0) -> 1 | O37: =MAX(MIN($I37-O$28*0.5,1),0) -> 1 | P37: =MAX(MIN($I37-P$28*0.5,1),0) -> 1 | Q37: =MAX(MIN($I37-Q$28*0.5,1),0) -> 1 | R37: =MAX(MIN($I37-R$28*0.5,1),0) -> 1 | S37: =MAX(MIN($I37-S$28*0.5,1),0) -> 0.95 | ... AY37: =MAX(MIN($I37-AY$28*0.5,1),0) -> 0
H38: 10 | I38: =K13-Total!D13 -> 1.39 | L38: =MAX(MIN($I38-L$28*0.5,1),0) -> 0.89 | M38: =MAX(MIN($I38-M$28*0.5,1),0) -> 0.39 | N38: =MAX(MIN($I38-N$28*0.5,1),0) -> 0 | O38: =MAX(MIN($I38-O$28*0.5,1),0) -> 0 | P38: =MAX(MIN($I38-P$28*0.5,1),0) -> 0 | Q38: =MAX(MIN($I38-Q$28*0.5,1),0) -> 0 | R38: =MAX(MIN($I38-R$28*0.5,1),0) -> 0 | S38: =MAX(MIN($I38-S$28*0.5,1),0) -> 0 | ... AY38: =MAX(MIN($I38-AY$28*0.5,1),0) -> 0
H39: 11 | I39: =K14-Total!D14 -> -3.1 | L39: =MAX(MIN($I39-L$28*0.5,1),0) -> 0 | M39: =MAX(MIN($I39-M$28*0.5,1),0) -> 0 | N39: =MAX(MIN($I39-N$28*0.5,1),0) -> 0 | O39: =MAX(MIN($I39-O$28*0.5,1),0) -> 0 | P39: =MAX(MIN($I39-P$28*0.5,1),0) -> 0 | Q39: =MAX(MIN($I39-Q$28*0.5,1),0) -> 0 | R39: =MAX(MIN($I39-R$28*0.5,1),0) -> 0 | S39: =MAX(MIN($I39-S$28*0.5,1),0) -> 0 | ... AY39: =MAX(MIN($I39-AY$28*0.5,1),0) -> 0
H40: 12 | I40: =K15-Total!D15 -> -0.6 | L40: =MAX(MIN($I40-L$28*0.5,1),0) -> 0 | M40: =MAX(MIN($I40-M$28*0.5,1),0) -> 0 | N40: =MAX(MIN($I40-N$28*0.5,1),0) -> 0 | O40: =MAX(MIN($I40-O$28*0.5,1),0) -> 0 | P40: =MAX(MIN($I40-P$28*0.5,1),0) -> 0 | Q40: =MAX(MIN($I40-Q$28*0.5,1),0) -> 0 | R40: =MAX(MIN($I40-R$28*0.5,1),0) -> 0 | S40: =MAX(MIN($I40-S$28*0.5,1),0) -> 0 | ... AY40: =MAX(MIN($I40-AY$28*0.5,1),0) -> 0
... H50: 22 | I50: =K25-Total!D25 -> -1.19 | L50: =MAX(MIN($I50-L$28*0.5,1),0) -> 0 | M50: =MAX(MIN($I50-M$28*0.5,1),0) -> 0 | N50: =MAX(MIN($I50-N$28*0.5,1),0) -> 0 | O50: =MAX(MIN($I50-O$28*0.5,1),0) -> 0 | P50: =MAX(MIN($I50-P$28*0.5,1),0) -> 0 | Q50: =MAX(MIN($I50-Q$28*0.5,1),0) -> 0 | R50: =MAX(MIN($I50-R$28*0.5,1),0) -> 0 | S50: =MAX(MIN($I50-S$28*0.5,1),0) -> 0 | ... AY50: =MAX(MIN($I50-AY$28*0.5,1),0) -> 0

Sheet Neuvilette
I2: Count | L2: Drops
B3: Run | C3: First | E3: Second | H3: Arcana | I3: First | J3: Second | K3: % | L3: 1 | M3: 2 | N3: 3 | O3: 4 | P3: 5 | Q3: 6 | R3: 7 | S3: 8 | T3: 9 | U3: 10 | V3: 11 | W3: 12 | X3: 13 | Y3: 14 | Z3: 15 | AA3: 16 | AB3: 17 | AC3: 18 | AD3: 19 | AE3: 20 | AF3: 21 | AG3: 22 | AH3: 23 | AI3: 24 | AJ3: 25 | AK3: 26 | AL3: 27 | AM3: 28 | AN3: 29 | AO3: 30 | AP3: 31 | AQ3: 32 | AR3: 33 | AS3: 34 | AT3: 35 | AU3: 36 | AV3: 37 | AW3: 38 | AX3: 39 | AY3: 40
B4: 1 | C4: 6 | D4: Lovers | E4: 18 | F4: Judgment | H4: 1 | I4: =COUNTIF($C$4:$C$16,H4) -> 1 | J4: =COUNTIF($E$4:$E$16,H4) -> 1 | K4: 7.52 | L4: =MAX(MIN($K4-L$3*0.5,1),0) -> 1 | M4: =MAX(MIN($K4-M$3*0.5,1),0) -> 1 | N4: =MAX(MIN($K4-N$3*0.5,1),0) -> 1 | O4: =MAX(MIN($K4-O$3*0.5,1),0) -> 1 | P4: =MAX(MIN($K4-P$3*0.5,1),0) -> 1 | Q4: =MAX(MIN($K4-Q$3*0.5,1),0) -> 1 | R4: =MAX(MIN($K4-R$3*0.5,1),0) -> 1 | S4: =MAX(MIN($K4-S$3*0.5,1),0) -> 1 | ... AY4: =MAX(MIN($K4-AY$3*0.5,1),0) -> 0
B5: 2 | C5: 14 | D5: Temperance | E5: 17 | F5: Star | H5: 2 | I5: =COUNTIF($C$4:$C$16,H5) -> 0 | J5: =COUNTIF($E$4:$E$16,H5) -> 1 | K5: 3.61 | L5: =MAX(MIN($K5-L$3*0.5,1),0) -> 1 | M5: =MAX(MIN($K5-M$3*0.5,1),0) -> 1 | N5: =MAX(MIN($K5-N$3*0.5,1),0) -> 1 | O5: =MAX(MIN($K5-O$3*0.5,1),0) -> 1 | P5: =MAX(MIN($K5-P$3*0.5,1),0) -> 1 | Q5: =MAX(MIN($K5-Q$3*0.5,1),0) -> 0.61 | R5: =MAX(MIN($K5-R$3*0.5,1),0) -> 0.11 | S5: =MAX(MIN($K5-S$3*0.5,1),0) -> 0 | ... AY5: =MAX(MIN($K5-AY$3*0.5,1),0) -> 0
B6: 3 | C6: 7 | D6: Chariot | E6: 8 | F6: Strength | H6: 3 | I6: =COUNTIF($C$4:$C$16,H6) -> 1 | J6: =COUNTIF($E$4:$E$16,H6) -> 1 | K6: 7.52 | L6: =MAX(MIN($K6-L$3*0.5,1),0) -> 1 | M6: =MAX(MIN($K6-M$3*0.5,1),0) -> 1 | N6: =MAX(MIN($K6-N$3*0.5,1),0) -> 1 | O6: =MAX(MIN($K6-O$3*0.5,1),0) -> 1 | P6: =MAX(MIN($K6-P$3*0.5,1),0) -> 1 | Q6: =MAX(MIN($K6-Q$3*0.5,1),0) -> 1 | R6: =MAX(MIN($K6-R$3*0.5,1),0) -> 1 | S6: =MAX(MIN($K6-S$3*0.5,1),0) -> 1 | ... AY6: =MAX(MIN($K6-AY$3*0.5,1),0) -> 0
B7: 4 | C7: 15 | D7: Devil | E7: 3 | F7: Empress | H7: 4 | I7: =COUNTIF($C$4:$C$16,H7) -> 0 | J7: =COUNTIF($E$4:$E$16,H7) -> 1 | K7: 3.61 | L7: =MAX(MIN($K7-L$3*0.5,1),0) -> 1 | M7: =MAX(MIN($K7-M$3*0.5,1),0) -> 1 | N7: =MAX(MIN($K7-N$3*0.5,1),0) -> 1 | O7: =MAX(MIN($K7-O$3*0.5,1),0) -> 1 | P7: =MAX(MIN($K7-P$3*0.5,1),0) -> 1 | Q7: =MAX(MIN($K7-Q$3*0.5,1),0) -> 0.61 | R7: =MAX(MIN($K7-R$3*0.5,1),0) -> 0.11 | S7: =MAX(MIN($K7-S$3*0.5,1),0) -> 0 | ... AY7: =MAX(MIN($K7-AY$3*0.5,1),0) -> 0
B8: 5 | C8: 14 | D8: Temperance | E8: 2 | F8: Priestess | H8: 5 | I8: =COUNTIF($C$4:$C$16,H8) -> 0 | J8: =COUNTIF($E$4:$E$16,H8) -> 0 | K8: 0 | L8: =MAX(MIN($K8-L$3*0.5,1),0) -> 0 | M8: =MAX(MIN($K8-M$3*0.5,1),0) -> 0 | N8: =MAX(MIN($K8-N$3*0.5,1),0) -> 0 | O8: =MAX(MIN($K8-O$3*0.5,1),0) -> 0 | P8: =MAX(MIN($K8-P$3*0.5,1),0) -> 0 | Q8: =MAX(MIN($K8-Q$3*0.5,1),0) -> 0 | R8: =MAX(MIN($K8-R$3*0.5,1),0) -> 0 | S8: =MAX(MIN($K8-S$3*0.5,1),0) -> 0 | ... AY8: =MAX(MIN($K8-AY$3*0.5,1),0) -> 0
B9: 6 | C9: 15 | D9: Devil | E9: 1 | F9: Magician | H9: 6 | I9: =COUNTIF($C$4:$C$16,H9) -> 1 | J9: =COUNTIF($E$4:$E$16,H9) -> 0 | K9: 3.75 | L9: =MAX(MIN($K9-L$3*0.5,1),0) -> 1 | M9: =MAX(MIN($K9-M$3*0.5,1),0) -> 1 | N9: =MAX(MIN($K9-N$3*0.5,1),0) -> 1 | O9: =MAX(MIN($K9-O$3*0.5,1),0) -> 1 | P9: =MAX(MIN($K9-P$3*0.5,1),0) -> 1 | Q9: =MAX(MIN($K9-Q$3*0.5,1),0) -> 0.75 | R9: =MAX(MIN($K9-R$3*0.5,1),0) -> 0.25 | S9: =MAX(MIN($K9-S$3*0.5,1),0) -> 0 | ... AY9: =MAX(MIN($K9-AY$3*0.5,1),0) -> 0
B10: 7 | C10: 15 | D10: Devil | E10: 7 | F10: Chariot | H10: 7 | I10: =COUNTIF($C$4:$C$16,H10) -> 1 | J10: =COUNTIF($E$4:$E$16,H10) -> 2 | K10: 11.29 | L10: =MAX(MIN($K10-L$3*0.5,1),0) -> 1 | M10: =MAX(MIN($K10-M$3*0.5,1),0) -> 1 | N10: =MAX(MIN($K10-N$3*0.5,1),0) -> 1 | O10: =MAX(MIN($K10-O$3*0.5,1),0) -> 1 | P10: =MAX(MIN($K10-P$3*0.5,1),0) -> 1 | Q10: =MAX(MIN($K10-Q$3*0.5,1),0) -> 1 | R10: =MAX(MIN($K10-R$3*0.5,1),0) -> 1 | S10: =MAX(MIN($K10-S$3*0.5,1),0) -> 1 | ... AY10: =MAX(MIN($K10-AY$3*0.5,1),0) -> 0
B11: 8 | C11: 14 | D11: Temperance | E11: 8 | F11: Strength | H11: 8 | I11: =COUNTIF($C$4:$C$16,H11) -> 0 | J11: =COUNTIF($E$4:$E$16,H11) -> 2 | K11: 7.23 | L11: =MAX(MIN($K11-L$3*0.5,1),0) -> 1 | M11: =MAX(MIN($K11-M$3*0.5,1),0) -> 1 | N11: =MAX(MIN($K11-N$3*0.5,1),0) -> 1 | O11: =MAX(MIN($K11-O$3*0.5,1),0) -> 1 | P11: =MAX(MIN($K11-P$3*0.5,1),0) -> 1 | Q11: =MAX(MIN($K11-Q$3*0.5,1),0) -> 1 | R11: =MAX(MIN($K11-R$3*0.5,1),0) -> 1 | S11: =MAX(MIN($K11-S$3*0.5,1),0) -> 1 | ... AY11: =MAX(MIN($K11-AY$3*0.5,1),0) -> 0
B12: 9 | C12: 14 | D12: Temperance | E12: 4 | F12: Emperor | H12: 9 | I12: =COUNTIF($C$4:$C$16,H12) -> 0 | J12: =COUNTIF($E$4:$E$16,H12) -> 0 | K12: 0 | L12: =MAX(MIN($K12-L$3*0.5,1),0) -> 0 | M12: =MAX(MIN($K12-M$3*0.5,1),0) -> 0 | N12: =MAX(MIN($K12-N$3*0.5,1),0) -> 0 | O12: =MAX(MIN($K12-O$3*0.5,1),0) -> 0 | P12: =MAX(MIN($K12-P$3*0.5,1),0) -> 0 | Q12: =MAX(MIN($K12-Q$3*0.5,1),0) -> 0 | R12: =MAX(MIN($K12-R$3*0.5,1),0) -> 0 | S12: =MAX(MIN($K12-S$3*0.5,1),0) -> 0 | ... AY12: =MAX(MIN($K12-AY$3*0.5,1),0) -> 0
B13: 10 | C13: 10 | D13: Wheel | E13: 7 | F13: Chariot | H13: 10 | I13: =COUNTIF($C$4:$C$16,H13) -> 1 | J13: =COUNTIF($E$4:$E$16,H13) -> 0 | K13: 3.75 | L13: =MAX(MIN($K13-L$3*0.5,1),0) -> 1 | M13: =MAX(MIN($K13-M$3*0.5,1),0) -> 1 | N13: =MAX(MIN($K13-N$3*0.5,1),0) -> 1 | O13: =MAX(MIN($K13-O$3*0.5,1),0) -> 1 | P13: =MAX(MIN($K13-P$3*0.5,1),0) -> 1 | Q13: =MAX(MIN($K13-Q$3*0.5,1),0) -> 0.75 | R13: =MAX(MIN($K13-R$3*0.5,1),0) -> 0.25 | S13: =MAX(MIN($K13-S$3*0.5,1),0) -> 0 | ... AY13: =MAX(MIN($K13-AY$3*0.5,1),0) -> 0
B14: 11 | C14: 1 | D14: Magician | E14: 13 | F14: Death | H14: 11 | I14: =COUNTIF($C$4:$C$16,H14) -> 0 | J14: =COUNTIF($E$4:$E$16,H14) -> 1 | K14: 3.61 | L14: =MAX(MIN($K14-L$3*0.5,1),0) -> 1 | M14: =MAX(MIN($K14-M$3*0.5,1),0) -> 1 | N14: =MAX(MIN($K14-N$3*0.5,1),0) -> 1 | O14: =MAX(MIN($K14-O$3*0.5,1),0) -> 1 | P14: =MAX(MIN($K14-P$3*0.5,1),0) -> 1 | Q14: =MAX(MIN($K14-Q$3*0.5,1),0) -> 0.61 | R14: =MAX(MIN($K14-R$3*0.5,1),0) -> 0.11 | S14: =MAX(MIN($K14-S$3*0.5,1),0) -> 0 | ... AY14: =MAX(MIN($K14-AY$3*0.5,1),0) -> 0
B15: 12 | C15: 3 | D15: Empress | E15: 16 | F15: Tower | H15: 12 | I15: =COUNTIF($C$4:$C$16,H15) -> 0 | J15: =COUNTIF($E$4:$E$16,H15) -> 0 | K15: 0 | L15: =MAX(MIN($K15-L$3*0.5,1),0) -> 0 | M15: =MAX(MIN($K15-M$3*0.5,1),0) -> 0 | N15: =MAX(MIN($K15-N$3*0.5,1),0) -> 0 | O15: =MAX(MIN($K15-O$3*0.5,1),0) -> 0 | P15: =MAX(MIN($K15-P$3*0.5,1),0) -> 0 | Q15: =MAX(MIN($K15-Q$3*0.5,1),0) -> 0 | R15: =MAX(MIN($K15-R$3*0.5,1),0) -> 0 | S15: =MAX(MIN($K15-S$3*0.5,1),0) -> 0 | ... AY15: =MAX(MIN($K15-AY$3*0.5,1),0) -> 0
B16: 13 | C16: 21 | D16: World | E16: 11 | F16: Justice | H16: 13 | I16: =COUNTIF($C$4:$C$16,H16) -> 0 | J16: =COUNTIF($E$4:$E$16,H16) -> 1 | K16: 3.61 | L16: =MAX(MIN($K16-L$3*0.5,1),0) -> 1 | M16: =MAX(MIN($K16-M$3*0.5,1),0) -> 1 | N16: =MAX(MIN($K16-N$3*0.5,1),0) -> 1 | O16: =MAX(MIN($K16-O$3*0.5,1),0) -> 1 | P16: =MAX(MIN($K16-P$3*0.5,1),0) -> 1 | Q16: =MAX(MIN($K16-Q$3*0.5,1),0) -> 0.61 | R16: =MAX(MIN($K16-R$3*0.5,1),0) -> 0.11 | S16: =MAX(MIN($K16-S$3*0.5,1),0) -> 0 | ... AY16: =MAX(MIN($K16-AY$3*0.5,1),0) -> 0
H17: 14 | I17: =COUNTIF($C$4:$C$16,H17) -> 4 | J17: =COUNTIF($E$4:$E$16,H17) -> 0 | K17: 17.52 | L17: =MAX(MIN($K17-L$3*0.5,1),0) -> 1 | M17: =MAX(MIN($K17-M$3*0.5,1),0) -> 1 | N17: =MAX(MIN($K17-N$3*0.5,1),0) -> 1 | O17: =MAX(MIN($K17-O$3*0.5,1),0) -> 1 | P17: =MAX(MIN($K17-P$3*0.5,1),0) -> 1 | Q17: =MAX(MIN($K17-Q$3*0.5,1),0) -> 1 | R17: =MAX(MIN($K17-R$3*0.5,1),0) -> 1 | S17: =MAX(MIN($K17-S$3*0.5,1),0) -> 1 | ... AY17: =MAX(MIN($K17-AY$3*0.5,1),0) -> 0
H18: 15 | I18: =COUNTIF($C$4:$C$16,H18) -> 3 | J18: =COUNTIF($E$4:$E$16,H18) -> 0 | K18: 12.38 | L18: =MAX(MIN($K18-L$3*0.5,1),0) -> 1 | M18: =MAX(MIN($K18-M$3*0.5,1),0) -> 1 | N18: =MAX(MIN($K18-N$3*0.5,1),0) -> 1 | O18: =MAX(MIN($K18-O$3*0.5,1),0) -> 1 | P18: =MAX(MIN($K18-P$3*0.5,1),0) -> 1 | Q18: =MAX(MIN($K18-Q$3*0.5,1),0) -> 1 | R18: =MAX(MIN($K18-R$3*0.5,1),0) -> 1 | S18: =MAX(MIN($K18-S$3*0.5,1),0) -> 1 | ... AY18: =MAX(MIN($K18-AY$3*0.5,1),0) -> 0
H19: 16 | I19: =COUNTIF($C$4:$C$16,H19) -> 0 | J19: =COUNTIF($E$4:$E$16,H19) -> 1 | K19: 3.61 | L19: =MAX(MIN($K19-L$3*0.5,1),0) -> 1 | M19: =MAX(MIN($K19-M$3*0.5,1),0) -> 1 | N19: =MAX(MIN($K19-N$3*0.5,1),0) -> 1 | O19: =MAX(MIN($K19-O$3*0.5,1),0) -> 1 | P19: =MAX(MIN($K19-P$3*0.5,1),0) -> 1 | Q19: =MAX(MIN($K19-Q$3*0.5,1),0) -> 0.61 | R19: =MAX(MIN($K19-R$3*0.5,1),0) -> 0.11 | S19: =MAX(MIN($K19-S$3*0.5,1),0) -> 0 | ... AY19: =MAX(MIN($K19-AY$3*0.5,1),0) -> 0
H20: 17 | I20: =COUNTIF($C$4:$C$16,H20) -> 0 | J20: =COUNTIF($E$4:$E$16,H20) -> 1 | K20: 3.61 | L20: =MAX(MIN($K20-L$3*0.5,1),0) -> 1 | M20: =MAX(MIN($K20-M$3*0.5,1),0) -> 1 | N20: =MAX(MIN($K20-N$3*0.5,1),0) -> 1 | O20: =MAX(MIN($K20-O$3*0.5,1),0) -> 1 | P20: =MAX(MIN($K20-P$3*0.5,1),0) -> 1 | Q20: =MAX(MIN($K20-Q$3*0.5,1),0) -> 0.61 | R20: =MAX(MIN($K20-R$3*0.5,1),0) -> 0.11 | S20: =MAX(MIN($K20-S$3*0.5,1),0) -> 0 | ... AY20: =MAX(MIN($K20-AY$3*0.5,1),0) -> 0
H21: 18 | I21: =COUNTIF($C$4:$C$16,H21) -> 0 | J21: =COUNTIF($E$4:$E$16,H21) -> 1 | K21: 0 | L21: =MAX(MIN($K21-L$3*0.5,1),0) -> 0 | M21: =MAX(MIN($K21-M$3*0.5,1),0) -> 0 | N21: =MAX(MIN($K21-N$3*0.5,1),0) -> 0 | O21: =MAX(MIN($K21-O$3*0.5,1),0) -> 0 | P21: =MAX(MIN($K21-P$3*0.5,1),0) -> 0 | Q21: =MAX(MIN($K21-Q$3*0.5,1),0) -> 0 | R21: =MAX(MIN($K21-R$3*0.5,1),0) -> 0 | S21: =MAX(MIN($K21-S$3*0.5,1),0) -> 0 | ... AY21: =MAX(MIN($K21-AY$3*0.5,1),0) -> 0
H22: 19 | I22: =COUNTIF($C$4:$C$16,H22) -> 0 | J22: =COUNTIF($E$4:$E$16,H22) -> 0 | K22: 0 | L22: =MAX(MIN($K22-L$3*0.5,1),0) -> 0 | M22: =MAX(MIN($K22-M$3*0.5,1),0) -> 0 | N22: =MAX(MIN($K22-N$3*0.5,1),0) -> 0 | O22: =MAX(MIN($K22-O$3*0.5,1),0) -> 0 | P22: =MAX(MIN($K22-P$3*0.5,1),0) -> 0 | Q22: =MAX(MIN($K22-Q$3*0.5,1),0) -> 0 | R22: =MAX(MIN($K22-R$3*0.5,1),0) -> 0 | S22: =MAX(MIN($K22-S$3*0.5,1),0) -> 0 | ... AY22: =MAX(MIN($K22-AY$3*0.5,1),0) -> 0
H23: 20 | I23: =COUNTIF($C$4:$C$16,H23) -> 0 | J23: =COUNTIF($E$4:$E$16,H23) -> 0 | K23: 3.61 | L23: =MAX(MIN($K23-L$3*0.5,1),0) -> 1 | M23: =MAX(MIN($K23-M$3*0.5,1),0) -> 1 | N23: =MAX(MIN($K23-N$3*0.5,1),0) -> 1 | O23: =MAX(MIN($K23-O$3*0.5,1),0) -> 1 | P23: =MAX(MIN($K23-P$3*0.5,1),0) -> 1 | Q23: =MAX(MIN($K23-Q$3*0.5,1),0) -> 0.61 | R23: =MAX(MIN($K23-R$3*0.5,1),0) -> 0.11 | S23: =MAX(MIN($K23-S$3*0.5,1),0) -> 0 | ... AY23: =MAX(MIN($K23-AY$3*0.5,1),0) -> 0
H24: 21 | I24: =COUNTIF($C$4:$C$16,H24) -> 1 | J24: =COUNTIF($E$4:$E$16,H24) -> 0 | K24: 3.75 | L24: =MAX(MIN($K24-L$3*0.5,1),0) -> 1 | M24: =MAX(MIN($K24-M$3*0.5,1),0) -> 1 | N24: =MAX(MIN($K24-N$3*0.5,1),0) -> 1 | O24: =MAX(MIN($K24-O$3*0.5,1),0) -> 1 | P24: =MAX(MIN($K24-P$3*0.5,1),0) -> 1 | Q24: =MAX(MIN($K24-Q$3*0.5,1),0) -> 0.75 | R24: =MAX(MIN($K24-R$3*0.5,1),0) -> 0.25 | S24: =MAX(MIN($K24-S$3*0.5,1),0) -> 0 | ... AY24: =MAX(MIN($K24-AY$3*0.5,1),0) -> 0
H25: 22 | I25: =COUNTIF($C$4:$C$16,H25) -> 0 | J25: =COUNTIF($E$4:$E$16,H25) -> 0 | K25: 0 | L25: =MAX(MIN($K25-L$3*0.5,1),0) -> 0 | M25: =MAX(MIN($K25-M$3*0.5,1),0) -> 0 | N25: =MAX(MIN($K25-N$3*0.5,1),0) -> 0 | O25: =MAX(MIN($K25-O$3*0.5,1),0) -> 0 | P25: =MAX(MIN($K25-P$3*0.5,1),0) -> 0 | Q25: =MAX(MIN($K25-Q$3*0.5,1),0) -> 0 | R25: =MAX(MIN($K25-R$3*0.5,1),0) -> 0 | S25: =MAX(MIN($K25-S$3*0.5,1),0) -> 0 | ... AY25: =MAX(MIN($K25-AY$3*0.5,1),0) -> 0
H26: Total | I26: =SUM(I4:I25)+SUM(J4:J25) -> 26
I27: Diff | L27: Drops
H28: Arcana | I28: % | L28: 1 | M28: 2 | N28: 3 | O28: 4 | P28: 5 | Q28: 6 | R28: 7 | S28: 8 | T28: 9 | U28: 10 | V28: 11 | W28: 12 | X28: 13 | Y28: 14 | Z28: 15 | AA28: 16 | AB28: 17 | AC28: 18 | AD28: 19 | AE28: 20 | AF28: 21 | AG28: 22 | AH28: 23 | AI28: 24 | AJ28: 25 | AK28: 26 | AL28: 27 | AM28: 28 | AN28: 29 | AO28: 30 | AP28: 31 | AQ28: 32 | AR28: 33 | AS28: 34 | AT28: 35 | AU28: 36 | AV28: 37 | AW28: 38 | AX28: 39 | AY28: 40
H29: 1 | I29: =K4-Total!D4 -> 4.48 | L29: =MAX(MIN($I29-L$28*0.5,1),0) -> 1 | M29: =MAX(MIN($I29-M$28*0.5,1),0) -> 1 | N29: =MAX(MIN($I29-N$28*0.5,1),0) -> 1 | O29: =MAX(MIN($I29-O$28*0.5,1),0) -> 1 | P29: =MAX(MIN($I29-P$28*0.5,1),0) -> 1 | Q29: =MAX(MIN($I29-Q$28*0.5,1),0) -> 1 | R29: =MAX(MIN($I29-R$28*0.5,1),0) -> 0.98 | S29: =MAX(MIN($I29-S$28*0.5,1),0) -> 0.48 | ... AY29: =MAX(MIN($I29-AY$28*0.5,1),0) -> 0
H30: 2 | I30: =K5-Total!D5 -> -2.51 | L30: =MAX(MIN($I30-L$28*0.5,1),0) -> 0 | M30: =MAX(MIN($I30-M$28*0.5,1),0) -> 0 | N30: =MAX(MIN($I30-N$28*0.5,1),0) -> 0 | O30: =MAX(MIN($I30-O$28*0.5,1),0) -> 0 | P30: =MAX(MIN($I30-P$28*0.5,1),0) -> 0 | Q30: =MAX(MIN($I30-Q$28*0.5,1),0) -> 0 | R30: =MAX(MIN($I30-R$28*0.5,1),0) -> 0 | S30: =MAX(MIN($I30-S$28*0.5,1),0) -> 0 | ... AY30: =MAX(MIN($I30-AY$28*0.5,1),0) -> 0
H31: 3 | I31: =K6-Total!D6 -> 0.79 | L31: =MAX(MIN($I31-L$28*0.5,1),0) -> 0.29 | M31: =MAX(MIN($I31-M$28*0.5,1),0) -> 0 | N31: =MAX(MIN($I31-N$28*0.5,1),0) -> 0 | O31: =MAX(MIN($I31-O$28*0.5,1),0) -> 0 | P31: =MAX(MIN($I31-P$28*0.5,1),0) -> 0 | Q31: =MAX(MIN($I31-Q$28*0.5,1),0) -> 0 | R31: =MAX(MIN($I31-R$28*0.5,1),0) -> 0 | S31: =MAX(MIN($I31-S$28*0.5,1),0) -> 0 | ... AY31: =MAX(MIN($I31-AY$28*0.5,1),0) -> 0
H32: 4 | I32: =K7-Total!D7 -> -0.04 | L32: =MAX(MIN($I32-L$28*0.5,1),0) -> 0 | M32: =MAX(MIN($I32-M$28*0.5,1),0) -> 0 | N32: =MAX(MIN($I32-N$28*0.5,1),0) -> 0 | O32: =MAX(MIN($I32-O$28*0.5,1),0) -> 0 | P32: =MAX(MIN($I32-P$28*0.5,1),0) -> 0 | Q32: =MAX(MIN($I32-Q$28*0.5,1),0) -> 0 | R32: =MAX(MIN($I32-R$28*0.5,1),0) -> 0 | S32: =MAX(MIN($I32-S$28*0.5,1),0) -> 0 | ... AY32: =MAX(MIN($I32-AY$28*0.5,1),0) -> 0
H33: 5 | I33: =K8-Total!D8 -> -3.02 | L33: =MAX(MIN($I33-L$28*0.5,1),0) -> 0 | M33: =MAX(MIN($I33-M$28*0.5,1),0) -> 0 | N33: =MAX(MIN($I33-N$28*0.5,1),0) -> 0 | O33: =MAX(MIN($I33-O$28*0.5,1),0) -> 0 | P33: =MAX(MIN($I33-P$28*0.5,1),0) -> 0 | Q33: =MAX(MIN($I33-Q$28*0.5,1),0) -> 0 | R33: =MAX(MIN($I33-R$28*0.5,1),0) -> 0 | S33: =MAX(MIN($I33-S$28*0.5,1),0) -> 0 | ... AY33: =MAX(MIN($I33-AY$28*0.5,1),0) -> 0
H34: 6 | I34: =K9-Total!D9 -> -6.55 | L34: =MAX(MIN($I34-L$28*0.5,1),0) -> 0 | M34: =MAX(MIN($I34-M$28*0.5,1),0) -> 0 | N34: =MAX(MIN($I34-N$28*0.5,1),0) -> 0 | O34: =MAX(MIN($I34-O$28*0.5,1),0) -> 0 | P34: =MAX(MIN($I34-P$28*0.5,1),0) -> 0 | Q34: =MAX(MIN($I34-Q$28*0.5,1),0) -> 0 | R34: =MAX(MIN($I34-R$28*0.5,1),0) -> 0 | S34: =MAX(MIN($I34-S$28*0.5,1),0) -> 0 | ... AY34: =MAX(MIN($I34-AY$28*0.5,1),0) -> 0
H35: 7 | I35: =K10-Total!D10 -> 1.71 | L35: =MAX(MIN($I35-L$28*0.5,1),0) -> 1 | M35: =MAX(MIN($I35-M$28*0.5,1),0) -> 0.71 | N35: =MAX(MIN($I35-N$28*0.5,1),0) -> 0.21 | O35: =MAX(MIN($I35-O$28*0.5,1),0) -> 0 | P35: =MAX(MIN($I35-P$28*0.5,1),0) -> 0 | Q35: =MAX(MIN($I35-Q$28*0.5,1),0) -> 0 | R35: =MAX(MIN($I35-R$28*0.5,1),0) -> 0 | S35: =MAX(MIN($I35-S$28*0.5,1),0) -> 0 | ... AY35: =MAX(MIN($I35-AY$28*0.5,1),0) -> 0
H36: 8 | I36: =K11-Total!D11 -> -0.02 | L36: =MAX(MIN($I36-L$28*0.5,1),0) -> 0 | M36: =MAX(MIN($I36-M$28*0.5,1),0) -> 0 | N36: =MAX(MIN($I36-N$28*0.5,1),0) -> 0 | O36: =MAX(MIN($I36-O$28*0.5,1),0) -> 0 | P36: =MAX(MIN($I36-P$28*0.5,1),0) -> 0 | Q36: =MAX(MIN($I36-Q$28*0.5,1),0) -> 0 | R36: =MAX(MIN($I36-R$28*0.5,1),0) -> 0 | S36: =MAX(MIN($I36-S$28*0.5,1),0) -> 0 | ... AY36: =MAX(MIN($I36-AY$28*0.5,1),0) -> 0
H37: 9 | I37: =K12-Total!D12 -> -2.4 | L37: =MAX(MIN($I37-L$28*0.5,1),0) -> 0 | M37: =MAX(MIN($I37-M$28*0.5,1),0) -> 0 | N37: =MAX(MIN($I37-N$28*0.5,1),0) -> 0 | O37: =MAX(MIN($I37-O$28*0.5,1),0) -> 0 | P37: =MAX(MIN($I37-P$28*0.5,1),0) -> 0 | Q37: =MAX(MIN($I37-Q$28*0.5,1),0) -> 0 | R37: =MAX(MIN($I37-R$28*0.5,1),0) -> 0 | S37: =MAX(MIN($I37-S$28*0.5,1),0) -> 0 | ... AY37: =MAX(MIN($I37-AY$28*0.5,1),0) -> 0
H38: 10 | I38: =K13-Total!D13 -> 1.32 | L38: =MAX(MIN($I38-L$28*0.5,1),0) -> 0.82 | M38: =MAX(MIN($I38-M$28*0.5,1),0) -> 0.32 | N38: =MAX(MIN($I38-N$28*0.5,1),0) -> 0 | O38: =MAX(MIN($I38-O$28*0.5,1),0) -> 0 | P38: =MAX(MIN($I38-P$28*0.5,1),0) -> 0 | Q38: =MAX(MIN($I38-Q$28*0.5,1),0) -> 0 | R38: =MAX(MIN($I38-R$28*0.5,1),0) -> 0 | S38: =MAX(MIN($I38-S$28*0.5,1),0) -> 0 | ... AY38: =MAX(MIN($I38-AY$28*0.5,1),0) -> 0
H39: 11 | I39: =K14-Total!D14 -> -3.17 | L39: =MAX(MIN($I39-L$28*0.5,1),0) -> 0 | M39: =MAX(MIN($I39-M$28*0.5,1),0) -> 0 | N39: =MAX(MIN($I39-N$28*0.5,1),0) -> 0 | O39: =MAX(MIN($I39-O$28*0.5,1),0) -> 0 | P39: =MAX(MIN($I39-P$28*0.5,1),0) -> 0 | Q39: =MAX(MIN($I39-Q$28*0.5,1),0) -> 0 | R39: =MAX(MIN($I39-R$28*0.5,1),0) -> 0 | S39: =MAX(MIN($I39-S$28*0.5,1),0) -> 0 | ... AY39: =MAX(MIN($I39-AY$28*0.5,1),0) -> 0
H40: 12 | I40: =K15-Total!D15 -> -0.6 | L40: =MAX(MIN($I40-L$28*0.5,1),0) -> 0 | M40: =MAX(MIN($I40-M$28*0.5,1),0) -> 0 | N40: =MAX(MIN($I40-N$28*0.5,1),0) -> 0 | O40: =MAX(MIN($I40-O$28*0.5,1),0) -> 0 | P40: =MAX(MIN($I40-P$28*0.5,1),0) -> 0 | Q40: =MAX(MIN($I40-Q$28*0.5,1),0) -> 0 | R40: =MAX(MIN($I40-R$28*0.5,1),0) -> 0 | S40: =MAX(MIN($I40-S$28*0.5,1),0) -> 0 | ... AY40: =MAX(MIN($I40-AY$28*0.5,1),0) -> 0
... H50: 22 | I50: =K25-Total!D25 -> -1.19 | L50: =MAX(MIN($I50-L$28*0.5,1),0) -> 0 | M50: =MAX(MIN($I50-M$28*0.5,1),0) -> 0 | N50: =MAX(MIN($I50-N$28*0.5,1),0) -> 0 | O50: =MAX(MIN($I50-O$28*0.5,1),0) -> 0 | P50: =MAX(MIN($I50-P$28*0.5,1),0) -> 0 | Q50: =MAX(MIN($I50-Q$28*0.5,1),0) -> 0 | R50: =MAX(MIN($I50-R$28*0.5,1),0) -> 0 | S50: =MAX(MIN($I50-S$28*0.5,1),0) -> 0 | ... AY50: =MAX(MIN($I50-AY$28*0.5,1),0) -> 0

Sheet Shogun
I2: Count | L2: Drops
B3: Run | C3: First | E3: Second | H3: Arcana | I3: First | J3: Second | K3: % | L3: 1 | M3: 2 | N3: 3 | O3: 4 | P3: 5 | Q3: 6 | R3: 7 | S3: 8 | T3: 9 | U3: 10 | V3: 11 | W3: 12 | X3: 13 | Y3: 14 | Z3: 15 | AA3: 16 | AB3: 17 | AC3: 18 | AD3: 19 | AE3: 20 | AF3: 21 | AG3: 22 | AH3: 23 | AI3: 24 | AJ3: 25 | AK3: 26 | AL3: 27 | AM3: 28 | AN3: 29 | AO3: 30 | AP3: 31 | AQ3: 32 | AR3: 33 | AS3: 34 | AT3: 35 | AU3: 36 | AV3: 37 | AW3: 38 | AX3: 39 | AY3: 40
B4: 1 | C4: 17 | D4: Star | E4: 8 | F4: Strength | H4: 1 | I4: =COUNTIF($C$4:$C$16,H4) -> 2 | J4: =COUNTIF($E$4:$E$16,H4) -> 0 | K4: 8 | L4: =MAX(MIN($K4-L$3*0.5,1),0) -> 1 | M4: =MAX(MIN($K4-M$3*0.5,1),0) -> 1 | N4: =MAX(MIN($K4-N$3*0.5,1),0) -> 1 | O4: =MAX(MIN($K4-O$3*0.5,1),0) -> 1 | P4: =MAX(MIN($K4-P$3*0.5,1),0) -> 1 | Q4: =MAX(MIN($K4-Q$3*0.5,1),0) -> 1 | R4: =MAX(MIN($K4-R$3*0.5,1),0) -> 1 | S4: =MAX(MIN($K4-S$3*0.5,1),0) -> 1 | ... AY4: =MAX(MIN($K4-AY$3*0.5,1),0) -> 0
